Traceback (most recent call last):
  File "/umbc/xfs1/jianwu/common/anaconda3/lib/python3.7/multiprocessing/forkserver.py", line 261, in main
  File "/umbc/xfs1/jianwu/common/anaconda3/lib/python3.7/multiprocessing/forkserver.py", line 297, in _serve_one
  File "/umbc/xfs1/jianwu/common/anaconda3/lib/python3.7/multiprocessing/spawn.py", line 114, in _main
  File "/umbc/xfs1/jianwu/common/anaconda3/lib/python3.7/multiprocessing/spawn.py", line 225, in prepare
  File "/umbc/xfs1/jianwu/common/anaconda3/lib/python3.7/multiprocessing/spawn.py", line 277, in _fixup_main_from_path
  File "/umbc/xfs1/jianwu/common/anaconda3/lib/python3.7/runpy.py", line 263, in run_path
  File "/umbc/xfs1/jianwu/common/anaconda3/lib/python3.7/runpy.py", line 96, in _run_module_code
  File "/umbc/xfs1/jianwu/common/anaconda3/lib/python3.7/runpy.py", line 85, in _run_code
  File "/umbc/xfs1/jianwu/common/MODIS_Aggregation/savioexe/test/4/t1/1m4ndk1.py", line 8, in <module>
  File "/umbc/xfs1/jianwu/common/anaconda3/lib/python3.7/site-packages/numpy/__init__.py", line 158, in <module>
  File "<frozen importlib._bootstrap>", line 983, in _find_and_load
  File "<frozen importlib._bootstrap>", line 967, in _find_and_load_unlocked
  File "<frozen importlib._bootstrap>", line 677, in _load_unlocked
  File "<frozen importlib._bootstrap_external>", line 724, in exec_module
  File "<frozen importlib._bootstrap_external>", line 859, in get_code
  File "<frozen importlib._bootstrap_external>", line 916, in get_data
OSError: [Errno 23] Too many open files in system: '/umbc/xfs1/jianwu/common/anaconda3/lib/python3.7/site-packages/numpy/fft/__init__.py'
distributed.scheduler - ERROR - Error in reevaluate occupancy
Traceback (most recent call last):
  File "/umbc/xfs1/jianwu/common/anaconda3/lib/python3.7/site-packages/distributed/scheduler.py", line 4290, in reevaluate_occupancy
    if self.proc.cpu_percent() < 50:
  File "/umbc/xfs1/jianwu/common/anaconda3/lib/python3.7/site-packages/psutil/__init__.py", line 987, in cpu_percent
    pt2 = self._proc.cpu_times()
  File "/umbc/xfs1/jianwu/common/anaconda3/lib/python3.7/site-packages/psutil/_pslinux.py", line 1508, in wrapper
    return fun(self, *args, **kwargs)
  File "/umbc/xfs1/jianwu/common/anaconda3/lib/python3.7/site-packages/psutil/_pslinux.py", line 1681, in cpu_times
    values = self._parse_stat_file()
  File "/umbc/xfs1/jianwu/common/anaconda3/lib/python3.7/site-packages/psutil/_common.py", line 340, in wrapper
    return fun(self)
  File "/umbc/xfs1/jianwu/common/anaconda3/lib/python3.7/site-packages/psutil/_pslinux.py", line 1547, in _parse_stat_file
    with open_binary("%s/%s/stat" % (self._procfs_path, self.pid)) as f:
  File "/umbc/xfs1/jianwu/common/anaconda3/lib/python3.7/site-packages/psutil/_common.py", line 582, in open_binary
    return open(fname, "rb", **kwargs)
OSError: [Errno 23] Too many open files in system: '/proc/279585/stat'
Traceback (most recent call last):
  File "/umbc/xfs1/jianwu/common/anaconda3/lib/python3.7/multiprocessing/forkserver.py", line 261, in main
  File "/umbc/xfs1/jianwu/common/anaconda3/lib/python3.7/multiprocessing/forkserver.py", line 297, in _serve_one
  File "/umbc/xfs1/jianwu/common/anaconda3/lib/python3.7/multiprocessing/spawn.py", line 114, in _main
  File "/umbc/xfs1/jianwu/common/anaconda3/lib/python3.7/multiprocessing/spawn.py", line 225, in prepare
  File "/umbc/xfs1/jianwu/common/anaconda3/lib/python3.7/multiprocessing/spawn.py", line 277, in _fixup_main_from_path
  File "/umbc/xfs1/jianwu/common/anaconda3/lib/python3.7/runpy.py", line 263, in run_path
  File "/umbc/xfs1/jianwu/common/anaconda3/lib/python3.7/runpy.py", line 96, in _run_module_code
  File "/umbc/xfs1/jianwu/common/anaconda3/lib/python3.7/runpy.py", line 85, in _run_code
  File "/umbc/xfs1/jianwu/common/MODIS_Aggregation/savioexe/test/4/t1/1m4ndk1.py", line 8, in <module>
  File "/umbc/xfs1/jianwu/common/anaconda3/lib/python3.7/site-packages/numpy/__init__.py", line 158, in <module>
  File "<frozen importlib._bootstrap>", line 983, in _find_and_load
  File "<frozen importlib._bootstrap>", line 967, in _find_and_load_unlocked
  File "<frozen importlib._bootstrap>", line 677, in _load_unlocked
  File "<frozen importlib._bootstrap_external>", line 724, in exec_module
  File "<frozen importlib._bootstrap_external>", line 859, in get_code
  File "<frozen importlib._bootstrap_external>", line 916, in get_data
OSError: [Errno 23] Too many open files in system: '/umbc/xfs1/jianwu/common/anaconda3/lib/python3.7/site-packages/numpy/fft/__init__.py'
Traceback (most recent call last):
  File "/umbc/xfs1/jianwu/common/anaconda3/lib/python3.7/multiprocessing/forkserver.py", line 261, in main
  File "/umbc/xfs1/jianwu/common/anaconda3/lib/python3.7/multiprocessing/forkserver.py", line 297, in _serve_one
  File "/umbc/xfs1/jianwu/common/anaconda3/lib/python3.7/multiprocessing/spawn.py", line 114, in _main
  File "/umbc/xfs1/jianwu/common/anaconda3/lib/python3.7/multiprocessing/spawn.py", line 225, in prepare
  File "/umbc/xfs1/jianwu/common/anaconda3/lib/python3.7/multiprocessing/spawn.py", line 277, in _fixup_main_from_path
  File "/umbc/xfs1/jianwu/common/anaconda3/lib/python3.7/runpy.py", line 263, in run_path
  File "/umbc/xfs1/jianwu/common/anaconda3/lib/python3.7/runpy.py", line 96, in _run_module_code
  File "/umbc/xfs1/jianwu/common/anaconda3/lib/python3.7/runpy.py", line 85, in _run_code
  File "/umbc/xfs1/jianwu/common/MODIS_Aggregation/savioexe/test/4/t1/1m4ndk1.py", line 8, in <module>
  File "/umbc/xfs1/jianwu/common/anaconda3/lib/python3.7/site-packages/numpy/__init__.py", line 158, in <module>
  File "<frozen importlib._bootstrap>", line 983, in _find_and_load
  File "<frozen importlib._bootstrap>", line 967, in _find_and_load_unlocked
  File "<frozen importlib._bootstrap>", line 677, in _load_unlocked
  File "<frozen importlib._bootstrap_external>", line 724, in exec_module
  File "<frozen importlib._bootstrap_external>", line 859, in get_code
  File "<frozen importlib._bootstrap_external>", line 916, in get_data
OSError: [Errno 23] Too many open files in system: '/umbc/xfs1/jianwu/common/anaconda3/lib/python3.7/site-packages/numpy/fft/__init__.py'
Traceback (most recent call last):
  File "/umbc/xfs1/jianwu/common/anaconda3/lib/python3.7/multiprocessing/forkserver.py", line 261, in main
  File "/umbc/xfs1/jianwu/common/anaconda3/lib/python3.7/multiprocessing/forkserver.py", line 297, in _serve_one
  File "/umbc/xfs1/jianwu/common/anaconda3/lib/python3.7/multiprocessing/spawn.py", line 114, in _main
  File "/umbc/xfs1/jianwu/common/anaconda3/lib/python3.7/multiprocessing/spawn.py", line 225, in prepare
  File "/umbc/xfs1/jianwu/common/anaconda3/lib/python3.7/multiprocessing/spawn.py", line 277, in _fixup_main_from_path
  File "/umbc/xfs1/jianwu/common/anaconda3/lib/python3.7/runpy.py", line 263, in run_path
  File "/umbc/xfs1/jianwu/common/anaconda3/lib/python3.7/runpy.py", line 96, in _run_module_code
  File "/umbc/xfs1/jianwu/common/anaconda3/lib/python3.7/runpy.py", line 85, in _run_code
  File "/umbc/xfs1/jianwu/common/MODIS_Aggregation/savioexe/test/4/t1/1m4ndk1.py", line 8, in <module>
  File "/umbc/xfs1/jianwu/common/anaconda3/lib/python3.7/site-packages/numpy/__init__.py", line 158, in <module>
  File "<frozen importlib._bootstrap>", line 983, in _find_and_load
  File "<frozen importlib._bootstrap>", line 967, in _find_and_load_unlocked
  File "<frozen importlib._bootstrap>", line 677, in _load_unlocked
  File "<frozen importlib._bootstrap_external>", line 724, in exec_module
  File "<frozen importlib._bootstrap_external>", line 859, in get_code
  File "<frozen importlib._bootstrap_external>", line 916, in get_data
OSError: [Errno 23] Too many open files in system: '/umbc/xfs1/jianwu/common/anaconda3/lib/python3.7/site-packages/numpy/fft/__init__.py'
Traceback (most recent call last):
  File "/umbc/xfs1/jianwu/common/anaconda3/lib/python3.7/multiprocessing/forkserver.py", line 261, in main
  File "/umbc/xfs1/jianwu/common/anaconda3/lib/python3.7/multiprocessing/forkserver.py", line 297, in _serve_one
  File "/umbc/xfs1/jianwu/common/anaconda3/lib/python3.7/multiprocessing/spawn.py", line 114, in _main
  File "/umbc/xfs1/jianwu/common/anaconda3/lib/python3.7/multiprocessing/spawn.py", line 225, in prepare
  File "/umbc/xfs1/jianwu/common/anaconda3/lib/python3.7/multiprocessing/spawn.py", line 277, in _fixup_main_from_path
  File "/umbc/xfs1/jianwu/common/anaconda3/lib/python3.7/runpy.py", line 263, in run_path
  File "/umbc/xfs1/jianwu/common/anaconda3/lib/python3.7/runpy.py", line 96, in _run_module_code
  File "/umbc/xfs1/jianwu/common/anaconda3/lib/python3.7/runpy.py", line 85, in _run_code
  File "/umbc/xfs1/jianwu/common/MODIS_Aggregation/savioexe/test/4/t1/1m4ndk1.py", line 8, in <module>
  File "/umbc/xfs1/jianwu/common/anaconda3/lib/python3.7/site-packages/numpy/__init__.py", line 158, in <module>
  File "<frozen importlib._bootstrap>", line 983, in _find_and_load
  File "<frozen importlib._bootstrap>", line 967, in _find_and_load_unlocked
  File "<frozen importlib._bootstrap>", line 677, in _load_unlocked
  File "<frozen importlib._bootstrap_external>", line 724, in exec_module
  File "<frozen importlib._bootstrap_external>", line 859, in get_code
  File "<frozen importlib._bootstrap_external>", line 916, in get_data
OSError: [Errno 23] Too many open files in system: '/umbc/xfs1/jianwu/common/anaconda3/lib/python3.7/site-packages/numpy/fft/__init__.py'
Traceback (most recent call last):
  File "/umbc/xfs1/jianwu/common/anaconda3/lib/python3.7/multiprocessing/forkserver.py", line 261, in main
  File "/umbc/xfs1/jianwu/common/anaconda3/lib/python3.7/multiprocessing/forkserver.py", line 297, in _serve_one
  File "/umbc/xfs1/jianwu/common/anaconda3/lib/python3.7/multiprocessing/spawn.py", line 114, in _main
  File "/umbc/xfs1/jianwu/common/anaconda3/lib/python3.7/multiprocessing/spawn.py", line 225, in prepare
  File "/umbc/xfs1/jianwu/common/anaconda3/lib/python3.7/multiprocessing/spawn.py", line 277, in _fixup_main_from_path
  File "/umbc/xfs1/jianwu/common/anaconda3/lib/python3.7/runpy.py", line 263, in run_path
  File "/umbc/xfs1/jianwu/common/anaconda3/lib/python3.7/runpy.py", line 96, in _run_module_code
  File "/umbc/xfs1/jianwu/common/anaconda3/lib/python3.7/runpy.py", line 85, in _run_code
  File "/umbc/xfs1/jianwu/common/MODIS_Aggregation/savioexe/test/4/t1/1m4ndk1.py", line 8, in <module>
  File "/umbc/xfs1/jianwu/common/anaconda3/lib/python3.7/site-packages/numpy/__init__.py", line 158, in <module>
  File "<frozen importlib._bootstrap>", line 983, in _find_and_load
  File "<frozen importlib._bootstrap>", line 967, in _find_and_load_unlocked
  File "<frozen importlib._bootstrap>", line 677, in _load_unlocked
  File "<frozen importlib._bootstrap_external>", line 724, in exec_module
  File "<frozen importlib._bootstrap_external>", line 859, in get_code
  File "<frozen importlib._bootstrap_external>", line 916, in get_data
OSError: [Errno 23] Too many open files in system: '/umbc/xfs1/jianwu/common/anaconda3/lib/python3.7/site-packages/numpy/fft/__init__.py'
Traceback (most recent call last):
  File "/umbc/xfs1/jianwu/common/anaconda3/lib/python3.7/multiprocessing/forkserver.py", line 261, in main
  File "/umbc/xfs1/jianwu/common/anaconda3/lib/python3.7/multiprocessing/forkserver.py", line 297, in _serve_one
  File "/umbc/xfs1/jianwu/common/anaconda3/lib/python3.7/multiprocessing/spawn.py", line 114, in _main
  File "/umbc/xfs1/jianwu/common/anaconda3/lib/python3.7/multiprocessing/spawn.py", line 225, in prepare
  File "/umbc/xfs1/jianwu/common/anaconda3/lib/python3.7/multiprocessing/spawn.py", line 277, in _fixup_main_from_path
  File "/umbc/xfs1/jianwu/common/anaconda3/lib/python3.7/runpy.py", line 263, in run_path
  File "/umbc/xfs1/jianwu/common/anaconda3/lib/python3.7/runpy.py", line 96, in _run_module_code
  File "/umbc/xfs1/jianwu/common/anaconda3/lib/python3.7/runpy.py", line 85, in _run_code
  File "/umbc/xfs1/jianwu/common/MODIS_Aggregation/savioexe/test/4/t1/1m4ndk1.py", line 8, in <module>
  File "/umbc/xfs1/jianwu/common/anaconda3/lib/python3.7/site-packages/numpy/__init__.py", line 158, in <module>
  File "<frozen importlib._bootstrap>", line 983, in _find_and_load
  File "<frozen importlib._bootstrap>", line 967, in _find_and_load_unlocked
  File "<frozen importlib._bootstrap>", line 677, in _load_unlocked
  File "<frozen importlib._bootstrap_external>", line 724, in exec_module
  File "<frozen importlib._bootstrap_external>", line 859, in get_code
  File "<frozen importlib._bootstrap_external>", line 916, in get_data
OSError: [Errno 23] Too many open files in system: '/umbc/xfs1/jianwu/common/anaconda3/lib/python3.7/site-packages/numpy/fft/__init__.py'
Traceback (most recent call last):
  File "/umbc/xfs1/jianwu/common/anaconda3/lib/python3.7/multiprocessing/forkserver.py", line 261, in main
  File "/umbc/xfs1/jianwu/common/anaconda3/lib/python3.7/multiprocessing/forkserver.py", line 297, in _serve_one
  File "/umbc/xfs1/jianwu/common/anaconda3/lib/python3.7/multiprocessing/spawn.py", line 114, in _main
  File "/umbc/xfs1/jianwu/common/anaconda3/lib/python3.7/multiprocessing/spawn.py", line 225, in prepare
  File "/umbc/xfs1/jianwu/common/anaconda3/lib/python3.7/multiprocessing/spawn.py", line 277, in _fixup_main_from_path
  File "/umbc/xfs1/jianwu/common/anaconda3/lib/python3.7/runpy.py", line 263, in run_path
  File "/umbc/xfs1/jianwu/common/anaconda3/lib/python3.7/runpy.py", line 96, in _run_module_code
  File "/umbc/xfs1/jianwu/common/anaconda3/lib/python3.7/runpy.py", line 85, in _run_code
  File "/umbc/xfs1/jianwu/common/MODIS_Aggregation/savioexe/test/4/t1/1m4ndk1.py", line 8, in <module>
  File "/umbc/xfs1/jianwu/common/anaconda3/lib/python3.7/site-packages/numpy/__init__.py", line 158, in <module>
  File "<frozen importlib._bootstrap>", line 983, in _find_and_load
  File "<frozen importlib._bootstrap>", line 967, in _find_and_load_unlocked
  File "<frozen importlib._bootstrap>", line 677, in _load_unlocked
  File "<frozen importlib._bootstrap_external>", line 724, in exec_module
  File "<frozen importlib._bootstrap_external>", line 859, in get_code
  File "<frozen importlib._bootstrap_external>", line 916, in get_data
OSError: [Errno 23] Too many open files in system: '/umbc/xfs1/jianwu/common/anaconda3/lib/python3.7/site-packages/numpy/fft/__init__.py'
Traceback (most recent call last):
  File "/umbc/xfs1/jianwu/common/anaconda3/lib/python3.7/multiprocessing/forkserver.py", line 261, in main
  File "/umbc/xfs1/jianwu/common/anaconda3/lib/python3.7/multiprocessing/forkserver.py", line 297, in _serve_one
  File "/umbc/xfs1/jianwu/common/anaconda3/lib/python3.7/multiprocessing/spawn.py", line 114, in _main
  File "/umbc/xfs1/jianwu/common/anaconda3/lib/python3.7/multiprocessing/spawn.py", line 225, in prepare
  File "/umbc/xfs1/jianwu/common/anaconda3/lib/python3.7/multiprocessing/spawn.py", line 277, in _fixup_main_from_path
  File "/umbc/xfs1/jianwu/common/anaconda3/lib/python3.7/runpy.py", line 263, in run_path
  File "/umbc/xfs1/jianwu/common/anaconda3/lib/python3.7/runpy.py", line 96, in _run_module_code
  File "/umbc/xfs1/jianwu/common/anaconda3/lib/python3.7/runpy.py", line 85, in _run_code
  File "/umbc/xfs1/jianwu/common/MODIS_Aggregation/savioexe/test/4/t1/1m4ndk1.py", line 8, in <module>
  File "/umbc/xfs1/jianwu/common/anaconda3/lib/python3.7/site-packages/numpy/__init__.py", line 158, in <module>
  File "<frozen importlib._bootstrap>", line 983, in _find_and_load
  File "<frozen importlib._bootstrap>", line 967, in _find_and_load_unlocked
  File "<frozen importlib._bootstrap>", line 677, in _load_unlocked
  File "<frozen importlib._bootstrap_external>", line 724, in exec_module
  File "<frozen importlib._bootstrap_external>", line 859, in get_code
  File "<frozen importlib._bootstrap_external>", line 916, in get_data
OSError: [Errno 23] Too many open files in system: '/umbc/xfs1/jianwu/common/anaconda3/lib/python3.7/site-packages/numpy/fft/__init__.py'
Traceback (most recent call last):
  File "/umbc/xfs1/jianwu/common/anaconda3/lib/python3.7/multiprocessing/forkserver.py", line 261, in main
  File "/umbc/xfs1/jianwu/common/anaconda3/lib/python3.7/multiprocessing/forkserver.py", line 297, in _serve_one
  File "/umbc/xfs1/jianwu/common/anaconda3/lib/python3.7/multiprocessing/spawn.py", line 114, in _main
  File "/umbc/xfs1/jianwu/common/anaconda3/lib/python3.7/multiprocessing/spawn.py", line 225, in prepare
  File "/umbc/xfs1/jianwu/common/anaconda3/lib/python3.7/multiprocessing/spawn.py", line 277, in _fixup_main_from_path
  File "/umbc/xfs1/jianwu/common/anaconda3/lib/python3.7/runpy.py", line 263, in run_path
  File "/umbc/xfs1/jianwu/common/anaconda3/lib/python3.7/runpy.py", line 96, in _run_module_code
  File "/umbc/xfs1/jianwu/common/anaconda3/lib/python3.7/runpy.py", line 85, in _run_code
  File "/umbc/xfs1/jianwu/common/MODIS_Aggregation/savioexe/test/4/t1/1m4ndk1.py", line 8, in <module>
  File "/umbc/xfs1/jianwu/common/anaconda3/lib/python3.7/site-packages/numpy/__init__.py", line 158, in <module>
  File "<frozen importlib._bootstrap>", line 983, in _find_and_load
  File "<frozen importlib._bootstrap>", line 967, in _find_and_load_unlocked
  File "<frozen importlib._bootstrap>", line 677, in _load_unlocked
  File "<frozen importlib._bootstrap_external>", line 724, in exec_module
  File "<frozen importlib._bootstrap_external>", line 859, in get_code
  File "<frozen importlib._bootstrap_external>", line 916, in get_data
OSError: [Errno 23] Too many open files in system: '/umbc/xfs1/jianwu/common/anaconda3/lib/python3.7/site-packages/numpy/fft/__init__.py'
Traceback (most recent call last):
  File "/umbc/xfs1/jianwu/common/anaconda3/lib/python3.7/multiprocessing/forkserver.py", line 261, in main
  File "/umbc/xfs1/jianwu/common/anaconda3/lib/python3.7/multiprocessing/forkserver.py", line 297, in _serve_one
  File "/umbc/xfs1/jianwu/common/anaconda3/lib/python3.7/multiprocessing/spawn.py", line 114, in _main
  File "/umbc/xfs1/jianwu/common/anaconda3/lib/python3.7/multiprocessing/spawn.py", line 225, in prepare
  File "/umbc/xfs1/jianwu/common/anaconda3/lib/python3.7/multiprocessing/spawn.py", line 277, in _fixup_main_from_path
  File "/umbc/xfs1/jianwu/common/anaconda3/lib/python3.7/runpy.py", line 263, in run_path
  File "/umbc/xfs1/jianwu/common/anaconda3/lib/python3.7/runpy.py", line 96, in _run_module_code
  File "/umbc/xfs1/jianwu/common/anaconda3/lib/python3.7/runpy.py", line 85, in _run_code
  File "/umbc/xfs1/jianwu/common/MODIS_Aggregation/savioexe/test/4/t1/1m4ndk1.py", line 8, in <module>
  File "/umbc/xfs1/jianwu/common/anaconda3/lib/python3.7/site-packages/numpy/__init__.py", line 150, in <module>
  File "/umbc/xfs1/jianwu/common/anaconda3/lib/python3.7/site-packages/numpy/_distributor_init.py", line 34, in <module>
ImportError: /umbc/xfs1/jianwu/common/anaconda3/lib/python3.7/site-packages/numpy/_mklinit.cpython-37m-x86_64-linux-gnu.so: cannot open shared object file: Too many open files in system
Traceback (most recent call last):
  File "/umbc/xfs1/jianwu/common/anaconda3/lib/python3.7/multiprocessing/forkserver.py", line 261, in main
  File "/umbc/xfs1/jianwu/common/anaconda3/lib/python3.7/multiprocessing/forkserver.py", line 297, in _serve_one
  File "/umbc/xfs1/jianwu/common/anaconda3/lib/python3.7/multiprocessing/spawn.py", line 114, in _main
  File "/umbc/xfs1/jianwu/common/anaconda3/lib/python3.7/multiprocessing/spawn.py", line 225, in prepare
  File "/umbc/xfs1/jianwu/common/anaconda3/lib/python3.7/multiprocessing/spawn.py", line 277, in _fixup_main_from_path
  File "/umbc/xfs1/jianwu/common/anaconda3/lib/python3.7/runpy.py", line 263, in run_path
  File "/umbc/xfs1/jianwu/common/anaconda3/lib/python3.7/runpy.py", line 96, in _run_module_code
  File "/umbc/xfs1/jianwu/common/anaconda3/lib/python3.7/runpy.py", line 85, in _run_code
  File "/umbc/xfs1/jianwu/common/MODIS_Aggregation/savioexe/test/4/t1/1m4ndk1.py", line 8, in <module>
  File "/umbc/xfs1/jianwu/common/anaconda3/lib/python3.7/site-packages/numpy/__init__.py", line 158, in <module>
  File "<frozen importlib._bootstrap>", line 983, in _find_and_load
  File "<frozen importlib._bootstrap>", line 967, in _find_and_load_unlocked
  File "<frozen importlib._bootstrap>", line 677, in _load_unlocked
  File "<frozen importlib._bootstrap_external>", line 724, in exec_module
  File "<frozen importlib._bootstrap_external>", line 859, in get_code
  File "<frozen importlib._bootstrap_external>", line 916, in get_data
OSError: [Errno 23] Too many open files in system: '/umbc/xfs1/jianwu/common/anaconda3/lib/python3.7/site-packages/numpy/fft/__init__.py'
Traceback (most recent call last):
  File "/umbc/xfs1/jianwu/common/anaconda3/lib/python3.7/multiprocessing/forkserver.py", line 261, in main
  File "/umbc/xfs1/jianwu/common/anaconda3/lib/python3.7/multiprocessing/forkserver.py", line 297, in _serve_one
  File "/umbc/xfs1/jianwu/common/anaconda3/lib/python3.7/multiprocessing/spawn.py", line 114, in _main
  File "/umbc/xfs1/jianwu/common/anaconda3/lib/python3.7/multiprocessing/spawn.py", line 225, in prepare
  File "/umbc/xfs1/jianwu/common/anaconda3/lib/python3.7/multiprocessing/spawn.py", line 277, in _fixup_main_from_path
  File "/umbc/xfs1/jianwu/common/anaconda3/lib/python3.7/runpy.py", line 263, in run_path
  File "/umbc/xfs1/jianwu/common/anaconda3/lib/python3.7/runpy.py", line 96, in _run_module_code
  File "/umbc/xfs1/jianwu/common/anaconda3/lib/python3.7/runpy.py", line 85, in _run_code
  File "/umbc/xfs1/jianwu/common/MODIS_Aggregation/savioexe/test/4/t1/1m4ndk1.py", line 8, in <module>
  File "/umbc/xfs1/jianwu/common/anaconda3/lib/python3.7/site-packages/numpy/__init__.py", line 158, in <module>
  File "<frozen importlib._bootstrap>", line 983, in _find_and_load
  File "<frozen importlib._bootstrap>", line 967, in _find_and_load_unlocked
  File "<frozen importlib._bootstrap>", line 677, in _load_unlocked
  File "<frozen importlib._bootstrap_external>", line 724, in exec_module
  File "<frozen importlib._bootstrap_external>", line 859, in get_code
  File "<frozen importlib._bootstrap_external>", line 916, in get_data
OSError: [Errno 23] Too many open files in system: '/umbc/xfs1/jianwu/common/anaconda3/lib/python3.7/site-packages/numpy/fft/__init__.py'
Traceback (most recent call last):
  File "/umbc/xfs1/jianwu/common/anaconda3/lib/python3.7/multiprocessing/forkserver.py", line 261, in main
  File "/umbc/xfs1/jianwu/common/anaconda3/lib/python3.7/multiprocessing/forkserver.py", line 297, in _serve_one
  File "/umbc/xfs1/jianwu/common/anaconda3/lib/python3.7/multiprocessing/spawn.py", line 114, in _main
  File "/umbc/xfs1/jianwu/common/anaconda3/lib/python3.7/multiprocessing/spawn.py", line 225, in prepare
  File "/umbc/xfs1/jianwu/common/anaconda3/lib/python3.7/multiprocessing/spawn.py", line 277, in _fixup_main_from_path
  File "/umbc/xfs1/jianwu/common/anaconda3/lib/python3.7/runpy.py", line 263, in run_path
  File "/umbc/xfs1/jianwu/common/anaconda3/lib/python3.7/runpy.py", line 96, in _run_module_code
  File "/umbc/xfs1/jianwu/common/anaconda3/lib/python3.7/runpy.py", line 85, in _run_code
  File "/umbc/xfs1/jianwu/common/MODIS_Aggregation/savioexe/test/4/t1/1m4ndk1.py", line 8, in <module>
  File "/umbc/xfs1/jianwu/common/anaconda3/lib/python3.7/site-packages/numpy/__init__.py", line 158, in <module>
  File "<frozen importlib._bootstrap>", line 983, in _find_and_load
  File "<frozen importlib._bootstrap>", line 967, in _find_and_load_unlocked
  File "<frozen importlib._bootstrap>", line 677, in _load_unlocked
  File "<frozen importlib._bootstrap_external>", line 724, in exec_module
  File "<frozen importlib._bootstrap_external>", line 859, in get_code
  File "<frozen importlib._bootstrap_external>", line 916, in get_data
OSError: [Errno 23] Too many open files in system: '/umbc/xfs1/jianwu/common/anaconda3/lib/python3.7/site-packages/numpy/fft/__init__.py'
Traceback (most recent call last):
  File "/umbc/xfs1/jianwu/common/anaconda3/lib/python3.7/multiprocessing/forkserver.py", line 261, in main
  File "/umbc/xfs1/jianwu/common/anaconda3/lib/python3.7/multiprocessing/forkserver.py", line 297, in _serve_one
  File "/umbc/xfs1/jianwu/common/anaconda3/lib/python3.7/multiprocessing/spawn.py", line 114, in _main
  File "/umbc/xfs1/jianwu/common/anaconda3/lib/python3.7/multiprocessing/spawn.py", line 225, in prepare
  File "/umbc/xfs1/jianwu/common/anaconda3/lib/python3.7/multiprocessing/spawn.py", line 277, in _fixup_main_from_path
  File "/umbc/xfs1/jianwu/common/anaconda3/lib/python3.7/runpy.py", line 263, in run_path
  File "/umbc/xfs1/jianwu/common/anaconda3/lib/python3.7/runpy.py", line 96, in _run_module_code
  File "/umbc/xfs1/jianwu/common/anaconda3/lib/python3.7/runpy.py", line 85, in _run_code
  File "/umbc/xfs1/jianwu/common/MODIS_Aggregation/savioexe/test/4/t1/1m4ndk1.py", line 8, in <module>
  File "/umbc/xfs1/jianwu/common/anaconda3/lib/python3.7/site-packages/numpy/__init__.py", line 158, in <module>
  File "<frozen importlib._bootstrap>", line 983, in _find_and_load
  File "<frozen importlib._bootstrap>", line 967, in _find_and_load_unlocked
  File "<frozen importlib._bootstrap>", line 677, in _load_unlocked
  File "<frozen importlib._bootstrap_external>", line 724, in exec_module
  File "<frozen importlib._bootstrap_external>", line 859, in get_code
  File "<frozen importlib._bootstrap_external>", line 916, in get_data
OSError: [Errno 23] Too many open files in system: '/umbc/xfs1/jianwu/common/anaconda3/lib/python3.7/site-packages/numpy/fft/__init__.py'
Traceback (most recent call last):
  File "/umbc/xfs1/jianwu/common/anaconda3/lib/python3.7/multiprocessing/forkserver.py", line 261, in main
  File "/umbc/xfs1/jianwu/common/anaconda3/lib/python3.7/multiprocessing/forkserver.py", line 297, in _serve_one
  File "/umbc/xfs1/jianwu/common/anaconda3/lib/python3.7/multiprocessing/spawn.py", line 114, in _main
  File "/umbc/xfs1/jianwu/common/anaconda3/lib/python3.7/multiprocessing/spawn.py", line 225, in prepare
  File "/umbc/xfs1/jianwu/common/anaconda3/lib/python3.7/multiprocessing/spawn.py", line 277, in _fixup_main_from_path
  File "/umbc/xfs1/jianwu/common/anaconda3/lib/python3.7/runpy.py", line 263, in run_path
  File "/umbc/xfs1/jianwu/common/anaconda3/lib/python3.7/runpy.py", line 96, in _run_module_code
  File "/umbc/xfs1/jianwu/common/anaconda3/lib/python3.7/runpy.py", line 85, in _run_code
  File "/umbc/xfs1/jianwu/common/MODIS_Aggregation/savioexe/test/4/t1/1m4ndk1.py", line 8, in <module>
  File "/umbc/xfs1/jianwu/common/anaconda3/lib/python3.7/site-packages/numpy/__init__.py", line 158, in <module>
  File "<frozen importlib._bootstrap>", line 983, in _find_and_load
  File "<frozen importlib._bootstrap>", line 967, in _find_and_load_unlocked
  File "<frozen importlib._bootstrap>", line 677, in _load_unlocked
  File "<frozen importlib._bootstrap_external>", line 724, in exec_module
  File "<frozen importlib._bootstrap_external>", line 859, in get_code
  File "<frozen importlib._bootstrap_external>", line 916, in get_data
OSError: [Errno 23] Too many open files in system: '/umbc/xfs1/jianwu/common/anaconda3/lib/python3.7/site-packages/numpy/fft/__init__.py'
Traceback (most recent call last):
  File "/umbc/xfs1/jianwu/common/anaconda3/lib/python3.7/multiprocessing/forkserver.py", line 261, in main
  File "/umbc/xfs1/jianwu/common/anaconda3/lib/python3.7/multiprocessing/forkserver.py", line 297, in _serve_one
  File "/umbc/xfs1/jianwu/common/anaconda3/lib/python3.7/multiprocessing/spawn.py", line 114, in _main
  File "/umbc/xfs1/jianwu/common/anaconda3/lib/python3.7/multiprocessing/spawn.py", line 225, in prepare
  File "/umbc/xfs1/jianwu/common/anaconda3/lib/python3.7/multiprocessing/spawn.py", line 277, in _fixup_main_from_path
  File "/umbc/xfs1/jianwu/common/anaconda3/lib/python3.7/runpy.py", line 263, in run_path
  File "/umbc/xfs1/jianwu/common/anaconda3/lib/python3.7/runpy.py", line 96, in _run_module_code
  File "/umbc/xfs1/jianwu/common/anaconda3/lib/python3.7/runpy.py", line 85, in _run_code
  File "/umbc/xfs1/jianwu/common/MODIS_Aggregation/savioexe/test/4/t1/1m4ndk1.py", line 8, in <module>
  File "/umbc/xfs1/jianwu/common/anaconda3/lib/python3.7/site-packages/numpy/__init__.py", line 158, in <module>
  File "<frozen importlib._bootstrap>", line 983, in _find_and_load
  File "<frozen importlib._bootstrap>", line 967, in _find_and_load_unlocked
  File "<frozen importlib._bootstrap>", line 677, in _load_unlocked
  File "<frozen importlib._bootstrap_external>", line 724, in exec_module
  File "<frozen importlib._bootstrap_external>", line 859, in get_code
  File "<frozen importlib._bootstrap_external>", line 916, in get_data
OSError: [Errno 23] Too many open files in system: '/umbc/xfs1/jianwu/common/anaconda3/lib/python3.7/site-packages/numpy/fft/__init__.py'
Traceback (most recent call last):
  File "/umbc/xfs1/jianwu/common/anaconda3/lib/python3.7/multiprocessing/forkserver.py", line 261, in main
  File "/umbc/xfs1/jianwu/common/anaconda3/lib/python3.7/multiprocessing/forkserver.py", line 297, in _serve_one
  File "/umbc/xfs1/jianwu/common/anaconda3/lib/python3.7/multiprocessing/spawn.py", line 114, in _main
  File "/umbc/xfs1/jianwu/common/anaconda3/lib/python3.7/multiprocessing/spawn.py", line 225, in prepare
  File "/umbc/xfs1/jianwu/common/anaconda3/lib/python3.7/multiprocessing/spawn.py", line 277, in _fixup_main_from_path
  File "/umbc/xfs1/jianwu/common/anaconda3/lib/python3.7/runpy.py", line 263, in run_path
  File "/umbc/xfs1/jianwu/common/anaconda3/lib/python3.7/runpy.py", line 96, in _run_module_code
  File "/umbc/xfs1/jianwu/common/anaconda3/lib/python3.7/runpy.py", line 85, in _run_code
  File "/umbc/xfs1/jianwu/common/MODIS_Aggregation/savioexe/test/4/t1/1m4ndk1.py", line 8, in <module>
  File "/umbc/xfs1/jianwu/common/anaconda3/lib/python3.7/site-packages/numpy/__init__.py", line 158, in <module>
  File "<frozen importlib._bootstrap>", line 983, in _find_and_load
  File "<frozen importlib._bootstrap>", line 967, in _find_and_load_unlocked
  File "<frozen importlib._bootstrap>", line 677, in _load_unlocked
  File "<frozen importlib._bootstrap_external>", line 724, in exec_module
  File "<frozen importlib._bootstrap_external>", line 859, in get_code
  File "<frozen importlib._bootstrap_external>", line 916, in get_data
OSError: [Errno 23] Too many open files in system: '/umbc/xfs1/jianwu/common/anaconda3/lib/python3.7/site-packages/numpy/fft/__init__.py'
Traceback (most recent call last):
  File "/umbc/xfs1/jianwu/common/anaconda3/lib/python3.7/multiprocessing/forkserver.py", line 261, in main
  File "/umbc/xfs1/jianwu/common/anaconda3/lib/python3.7/multiprocessing/forkserver.py", line 297, in _serve_one
  File "/umbc/xfs1/jianwu/common/anaconda3/lib/python3.7/multiprocessing/spawn.py", line 114, in _main
  File "/umbc/xfs1/jianwu/common/anaconda3/lib/python3.7/multiprocessing/spawn.py", line 225, in prepare
  File "/umbc/xfs1/jianwu/common/anaconda3/lib/python3.7/multiprocessing/spawn.py", line 277, in _fixup_main_from_path
  File "/umbc/xfs1/jianwu/common/anaconda3/lib/python3.7/runpy.py", line 263, in run_path
  File "/umbc/xfs1/jianwu/common/anaconda3/lib/python3.7/runpy.py", line 96, in _run_module_code
  File "/umbc/xfs1/jianwu/common/anaconda3/lib/python3.7/runpy.py", line 85, in _run_code
  File "/umbc/xfs1/jianwu/common/MODIS_Aggregation/savioexe/test/4/t1/1m4ndk1.py", line 8, in <module>
  File "/umbc/xfs1/jianwu/common/anaconda3/lib/python3.7/site-packages/numpy/__init__.py", line 158, in <module>
  File "<frozen importlib._bootstrap>", line 983, in _find_and_load
  File "<frozen importlib._bootstrap>", line 967, in _find_and_load_unlocked
  File "<frozen importlib._bootstrap>", line 677, in _load_unlocked
  File "<frozen importlib._bootstrap_external>", line 724, in exec_module
  File "<frozen importlib._bootstrap_external>", line 859, in get_code
  File "<frozen importlib._bootstrap_external>", line 916, in get_data
OSError: [Errno 23] Too many open files in system: '/umbc/xfs1/jianwu/common/anaconda3/lib/python3.7/site-packages/numpy/fft/__init__.py'
Traceback (most recent call last):
  File "/umbc/xfs1/jianwu/common/anaconda3/lib/python3.7/multiprocessing/forkserver.py", line 261, in main
  File "/umbc/xfs1/jianwu/common/anaconda3/lib/python3.7/multiprocessing/forkserver.py", line 297, in _serve_one
  File "/umbc/xfs1/jianwu/common/anaconda3/lib/python3.7/multiprocessing/spawn.py", line 114, in _main
  File "/umbc/xfs1/jianwu/common/anaconda3/lib/python3.7/multiprocessing/spawn.py", line 225, in prepare
  File "/umbc/xfs1/jianwu/common/anaconda3/lib/python3.7/multiprocessing/spawn.py", line 277, in _fixup_main_from_path
  File "/umbc/xfs1/jianwu/common/anaconda3/lib/python3.7/runpy.py", line 263, in run_path
  File "/umbc/xfs1/jianwu/common/anaconda3/lib/python3.7/runpy.py", line 96, in _run_module_code
  File "/umbc/xfs1/jianwu/common/anaconda3/lib/python3.7/runpy.py", line 85, in _run_code
  File "/umbc/xfs1/jianwu/common/MODIS_Aggregation/savioexe/test/4/t1/1m4ndk1.py", line 8, in <module>
  File "/umbc/xfs1/jianwu/common/anaconda3/lib/python3.7/site-packages/numpy/__init__.py", line 158, in <module>
  File "<frozen importlib._bootstrap>", line 983, in _find_and_load
  File "<frozen importlib._bootstrap>", line 967, in _find_and_load_unlocked
  File "<frozen importlib._bootstrap>", line 677, in _load_unlocked
  File "<frozen importlib._bootstrap_external>", line 724, in exec_module
  File "<frozen importlib._bootstrap_external>", line 859, in get_code
  File "<frozen importlib._bootstrap_external>", line 916, in get_data
OSError: [Errno 23] Too many open files in system: '/umbc/xfs1/jianwu/common/anaconda3/lib/python3.7/site-packages/numpy/fft/__init__.py'
Traceback (most recent call last):
  File "/umbc/xfs1/jianwu/common/anaconda3/lib/python3.7/multiprocessing/forkserver.py", line 261, in main
  File "/umbc/xfs1/jianwu/common/anaconda3/lib/python3.7/multiprocessing/forkserver.py", line 297, in _serve_one
  File "/umbc/xfs1/jianwu/common/anaconda3/lib/python3.7/multiprocessing/spawn.py", line 114, in _main
  File "/umbc/xfs1/jianwu/common/anaconda3/lib/python3.7/multiprocessing/spawn.py", line 225, in prepare
  File "/umbc/xfs1/jianwu/common/anaconda3/lib/python3.7/multiprocessing/spawn.py", line 277, in _fixup_main_from_path
  File "/umbc/xfs1/jianwu/common/anaconda3/lib/python3.7/runpy.py", line 263, in run_path
  File "/umbc/xfs1/jianwu/common/anaconda3/lib/python3.7/runpy.py", line 96, in _run_module_code
  File "/umbc/xfs1/jianwu/common/anaconda3/lib/python3.7/runpy.py", line 85, in _run_code
  File "/umbc/xfs1/jianwu/common/MODIS_Aggregation/savioexe/test/4/t1/1m4ndk1.py", line 8, in <module>
  File "/umbc/xfs1/jianwu/common/anaconda3/lib/python3.7/site-packages/numpy/__init__.py", line 158, in <module>
  File "<frozen importlib._bootstrap>", line 983, in _find_and_load
  File "<frozen importlib._bootstrap>", line 967, in _find_and_load_unlocked
  File "<frozen importlib._bootstrap>", line 677, in _load_unlocked
  File "<frozen importlib._bootstrap_external>", line 724, in exec_module
  File "<frozen importlib._bootstrap_external>", line 859, in get_code
  File "<frozen importlib._bootstrap_external>", line 916, in get_data
OSError: [Errno 23] Too many open files in system: '/umbc/xfs1/jianwu/common/anaconda3/lib/python3.7/site-packages/numpy/fft/__init__.py'
Traceback (most recent call last):
  File "/umbc/xfs1/jianwu/common/anaconda3/lib/python3.7/multiprocessing/forkserver.py", line 261, in main
  File "/umbc/xfs1/jianwu/common/anaconda3/lib/python3.7/multiprocessing/forkserver.py", line 297, in _serve_one
  File "/umbc/xfs1/jianwu/common/anaconda3/lib/python3.7/multiprocessing/spawn.py", line 114, in _main
  File "/umbc/xfs1/jianwu/common/anaconda3/lib/python3.7/multiprocessing/spawn.py", line 225, in prepare
  File "/umbc/xfs1/jianwu/common/anaconda3/lib/python3.7/multiprocessing/spawn.py", line 277, in _fixup_main_from_path
  File "/umbc/xfs1/jianwu/common/anaconda3/lib/python3.7/runpy.py", line 263, in run_path
  File "/umbc/xfs1/jianwu/common/anaconda3/lib/python3.7/runpy.py", line 96, in _run_module_code
  File "/umbc/xfs1/jianwu/common/anaconda3/lib/python3.7/runpy.py", line 85, in _run_code
  File "/umbc/xfs1/jianwu/common/MODIS_Aggregation/savioexe/test/4/t1/1m4ndk1.py", line 8, in <module>
  File "/umbc/xfs1/jianwu/common/anaconda3/lib/python3.7/site-packages/numpy/__init__.py", line 158, in <module>
  File "<frozen importlib._bootstrap>", line 983, in _find_and_load
  File "<frozen importlib._bootstrap>", line 967, in _find_and_load_unlocked
  File "<frozen importlib._bootstrap>", line 677, in _load_unlocked
  File "<frozen importlib._bootstrap_external>", line 724, in exec_module
  File "<frozen importlib._bootstrap_external>", line 859, in get_code
  File "<frozen importlib._bootstrap_external>", line 916, in get_data
OSError: [Errno 23] Too many open files in system: '/umbc/xfs1/jianwu/common/anaconda3/lib/python3.7/site-packages/numpy/fft/__init__.py'
Traceback (most recent call last):
  File "/umbc/xfs1/jianwu/common/anaconda3/lib/python3.7/multiprocessing/forkserver.py", line 261, in main
  File "/umbc/xfs1/jianwu/common/anaconda3/lib/python3.7/multiprocessing/forkserver.py", line 297, in _serve_one
  File "/umbc/xfs1/jianwu/common/anaconda3/lib/python3.7/multiprocessing/spawn.py", line 114, in _main
  File "/umbc/xfs1/jianwu/common/anaconda3/lib/python3.7/multiprocessing/spawn.py", line 225, in prepare
  File "/umbc/xfs1/jianwu/common/anaconda3/lib/python3.7/multiprocessing/spawn.py", line 277, in _fixup_main_from_path
  File "/umbc/xfs1/jianwu/common/anaconda3/lib/python3.7/runpy.py", line 263, in run_path
  File "/umbc/xfs1/jianwu/common/anaconda3/lib/python3.7/runpy.py", line 96, in _run_module_code
  File "/umbc/xfs1/jianwu/common/anaconda3/lib/python3.7/runpy.py", line 85, in _run_code
  File "/umbc/xfs1/jianwu/common/MODIS_Aggregation/savioexe/test/4/t1/1m4ndk1.py", line 8, in <module>
  File "/umbc/xfs1/jianwu/common/anaconda3/lib/python3.7/site-packages/numpy/__init__.py", line 158, in <module>
  File "<frozen importlib._bootstrap>", line 983, in _find_and_load
  File "<frozen importlib._bootstrap>", line 967, in _find_and_load_unlocked
  File "<frozen importlib._bootstrap>", line 677, in _load_unlocked
  File "<frozen importlib._bootstrap_external>", line 724, in exec_module
  File "<frozen importlib._bootstrap_external>", line 859, in get_code
  File "<frozen importlib._bootstrap_external>", line 916, in get_data
OSError: [Errno 23] Too many open files in system: '/umbc/xfs1/jianwu/common/anaconda3/lib/python3.7/site-packages/numpy/fft/__init__.py'
Traceback (most recent call last):
  File "/umbc/xfs1/jianwu/common/anaconda3/lib/python3.7/multiprocessing/forkserver.py", line 261, in main
  File "/umbc/xfs1/jianwu/common/anaconda3/lib/python3.7/multiprocessing/forkserver.py", line 297, in _serve_one
  File "/umbc/xfs1/jianwu/common/anaconda3/lib/python3.7/multiprocessing/spawn.py", line 114, in _main
  File "/umbc/xfs1/jianwu/common/anaconda3/lib/python3.7/multiprocessing/spawn.py", line 225, in prepare
  File "/umbc/xfs1/jianwu/common/anaconda3/lib/python3.7/multiprocessing/spawn.py", line 277, in _fixup_main_from_path
  File "/umbc/xfs1/jianwu/common/anaconda3/lib/python3.7/runpy.py", line 263, in run_path
  File "/umbc/xfs1/jianwu/common/anaconda3/lib/python3.7/runpy.py", line 96, in _run_module_code
  File "/umbc/xfs1/jianwu/common/anaconda3/lib/python3.7/runpy.py", line 85, in _run_code
  File "/umbc/xfs1/jianwu/common/MODIS_Aggregation/savioexe/test/4/t1/1m4ndk1.py", line 8, in <module>
  File "/umbc/xfs1/jianwu/common/anaconda3/lib/python3.7/site-packages/numpy/__init__.py", line 158, in <module>
  File "<frozen importlib._bootstrap>", line 983, in _find_and_load
  File "<frozen importlib._bootstrap>", line 967, in _find_and_load_unlocked
  File "<frozen importlib._bootstrap>", line 677, in _load_unlocked
  File "<frozen importlib._bootstrap_external>", line 724, in exec_module
  File "<frozen importlib._bootstrap_external>", line 859, in get_code
  File "<frozen importlib._bootstrap_external>", line 916, in get_data
OSError: [Errno 23] Too many open files in system: '/umbc/xfs1/jianwu/common/anaconda3/lib/python3.7/site-packages/numpy/fft/__init__.py'
Traceback (most recent call last):
  File "/umbc/xfs1/jianwu/common/anaconda3/lib/python3.7/multiprocessing/forkserver.py", line 261, in main
  File "/umbc/xfs1/jianwu/common/anaconda3/lib/python3.7/multiprocessing/forkserver.py", line 297, in _serve_one
  File "/umbc/xfs1/jianwu/common/anaconda3/lib/python3.7/multiprocessing/spawn.py", line 114, in _main
  File "/umbc/xfs1/jianwu/common/anaconda3/lib/python3.7/multiprocessing/spawn.py", line 225, in prepare
  File "/umbc/xfs1/jianwu/common/anaconda3/lib/python3.7/multiprocessing/spawn.py", line 277, in _fixup_main_from_path
  File "/umbc/xfs1/jianwu/common/anaconda3/lib/python3.7/runpy.py", line 263, in run_path
  File "/umbc/xfs1/jianwu/common/anaconda3/lib/python3.7/runpy.py", line 96, in _run_module_code
  File "/umbc/xfs1/jianwu/common/anaconda3/lib/python3.7/runpy.py", line 85, in _run_code
  File "/umbc/xfs1/jianwu/common/MODIS_Aggregation/savioexe/test/4/t1/1m4ndk1.py", line 8, in <module>
  File "/umbc/xfs1/jianwu/common/anaconda3/lib/python3.7/site-packages/numpy/__init__.py", line 158, in <module>
  File "<frozen importlib._bootstrap>", line 983, in _find_and_load
  File "<frozen importlib._bootstrap>", line 967, in _find_and_load_unlocked
  File "<frozen importlib._bootstrap>", line 677, in _load_unlocked
  File "<frozen importlib._bootstrap_external>", line 724, in exec_module
  File "<frozen importlib._bootstrap_external>", line 859, in get_code
  File "<frozen importlib._bootstrap_external>", line 916, in get_data
OSError: [Errno 23] Too many open files in system: '/umbc/xfs1/jianwu/common/anaconda3/lib/python3.7/site-packages/numpy/fft/__init__.py'
Traceback (most recent call last):
  File "/umbc/xfs1/jianwu/common/anaconda3/lib/python3.7/multiprocessing/forkserver.py", line 261, in main
  File "/umbc/xfs1/jianwu/common/anaconda3/lib/python3.7/multiprocessing/forkserver.py", line 297, in _serve_one
  File "/umbc/xfs1/jianwu/common/anaconda3/lib/python3.7/multiprocessing/spawn.py", line 114, in _main
  File "/umbc/xfs1/jianwu/common/anaconda3/lib/python3.7/multiprocessing/spawn.py", line 225, in prepare
  File "/umbc/xfs1/jianwu/common/anaconda3/lib/python3.7/multiprocessing/spawn.py", line 277, in _fixup_main_from_path
  File "/umbc/xfs1/jianwu/common/anaconda3/lib/python3.7/runpy.py", line 263, in run_path
  File "/umbc/xfs1/jianwu/common/anaconda3/lib/python3.7/runpy.py", line 96, in _run_module_code
  File "/umbc/xfs1/jianwu/common/anaconda3/lib/python3.7/runpy.py", line 85, in _run_code
  File "/umbc/xfs1/jianwu/common/MODIS_Aggregation/savioexe/test/4/t1/1m4ndk1.py", line 8, in <module>
  File "/umbc/xfs1/jianwu/common/anaconda3/lib/python3.7/site-packages/numpy/__init__.py", line 158, in <module>
  File "<frozen importlib._bootstrap>", line 983, in _find_and_load
  File "<frozen importlib._bootstrap>", line 967, in _find_and_load_unlocked
  File "<frozen importlib._bootstrap>", line 677, in _load_unlocked
  File "<frozen importlib._bootstrap_external>", line 724, in exec_module
  File "<frozen importlib._bootstrap_external>", line 859, in get_code
  File "<frozen importlib._bootstrap_external>", line 916, in get_data
OSError: [Errno 23] Too many open files in system: '/umbc/xfs1/jianwu/common/anaconda3/lib/python3.7/site-packages/numpy/fft/__init__.py'
Traceback (most recent call last):
  File "/umbc/xfs1/jianwu/common/anaconda3/lib/python3.7/multiprocessing/forkserver.py", line 261, in main
  File "/umbc/xfs1/jianwu/common/anaconda3/lib/python3.7/multiprocessing/forkserver.py", line 297, in _serve_one
  File "/umbc/xfs1/jianwu/common/anaconda3/lib/python3.7/multiprocessing/spawn.py", line 114, in _main
  File "/umbc/xfs1/jianwu/common/anaconda3/lib/python3.7/multiprocessing/spawn.py", line 225, in prepare
  File "/umbc/xfs1/jianwu/common/anaconda3/lib/python3.7/multiprocessing/spawn.py", line 277, in _fixup_main_from_path
  File "/umbc/xfs1/jianwu/common/anaconda3/lib/python3.7/runpy.py", line 263, in run_path
  File "/umbc/xfs1/jianwu/common/anaconda3/lib/python3.7/runpy.py", line 96, in _run_module_code
  File "/umbc/xfs1/jianwu/common/anaconda3/lib/python3.7/runpy.py", line 85, in _run_code
  File "/umbc/xfs1/jianwu/common/MODIS_Aggregation/savioexe/test/4/t1/1m4ndk1.py", line 8, in <module>
  File "/umbc/xfs1/jianwu/common/anaconda3/lib/python3.7/site-packages/numpy/__init__.py", line 158, in <module>
  File "<frozen importlib._bootstrap>", line 983, in _find_and_load
  File "<frozen importlib._bootstrap>", line 967, in _find_and_load_unlocked
  File "<frozen importlib._bootstrap>", line 677, in _load_unlocked
  File "<frozen importlib._bootstrap_external>", line 724, in exec_module
  File "<frozen importlib._bootstrap_external>", line 859, in get_code
  File "<frozen importlib._bootstrap_external>", line 916, in get_data
OSError: [Errno 23] Too many open files in system: '/umbc/xfs1/jianwu/common/anaconda3/lib/python3.7/site-packages/numpy/fft/__init__.py'
Traceback (most recent call last):
  File "/umbc/xfs1/jianwu/common/anaconda3/lib/python3.7/multiprocessing/forkserver.py", line 261, in main
  File "/umbc/xfs1/jianwu/common/anaconda3/lib/python3.7/multiprocessing/forkserver.py", line 297, in _serve_one
  File "/umbc/xfs1/jianwu/common/anaconda3/lib/python3.7/multiprocessing/spawn.py", line 114, in _main
  File "/umbc/xfs1/jianwu/common/anaconda3/lib/python3.7/multiprocessing/spawn.py", line 225, in prepare
  File "/umbc/xfs1/jianwu/common/anaconda3/lib/python3.7/multiprocessing/spawn.py", line 277, in _fixup_main_from_path
  File "/umbc/xfs1/jianwu/common/anaconda3/lib/python3.7/runpy.py", line 263, in run_path
  File "/umbc/xfs1/jianwu/common/anaconda3/lib/python3.7/runpy.py", line 96, in _run_module_code
  File "/umbc/xfs1/jianwu/common/anaconda3/lib/python3.7/runpy.py", line 85, in _run_code
  File "/umbc/xfs1/jianwu/common/MODIS_Aggregation/savioexe/test/4/t1/1m4ndk1.py", line 8, in <module>
  File "/umbc/xfs1/jianwu/common/anaconda3/lib/python3.7/site-packages/numpy/__init__.py", line 158, in <module>
  File "<frozen importlib._bootstrap>", line 983, in _find_and_load
  File "<frozen importlib._bootstrap>", line 967, in _find_and_load_unlocked
  File "<frozen importlib._bootstrap>", line 677, in _load_unlocked
  File "<frozen importlib._bootstrap_external>", line 724, in exec_module
  File "<frozen importlib._bootstrap_external>", line 859, in get_code
  File "<frozen importlib._bootstrap_external>", line 916, in get_data
OSError: [Errno 23] Too many open files in system: '/umbc/xfs1/jianwu/common/anaconda3/lib/python3.7/site-packages/numpy/fft/__init__.py'
Traceback (most recent call last):
  File "/umbc/xfs1/jianwu/common/anaconda3/lib/python3.7/multiprocessing/forkserver.py", line 261, in main
  File "/umbc/xfs1/jianwu/common/anaconda3/lib/python3.7/multiprocessing/forkserver.py", line 297, in _serve_one
  File "/umbc/xfs1/jianwu/common/anaconda3/lib/python3.7/multiprocessing/spawn.py", line 114, in _main
  File "/umbc/xfs1/jianwu/common/anaconda3/lib/python3.7/multiprocessing/spawn.py", line 225, in prepare
  File "/umbc/xfs1/jianwu/common/anaconda3/lib/python3.7/multiprocessing/spawn.py", line 277, in _fixup_main_from_path
  File "/umbc/xfs1/jianwu/common/anaconda3/lib/python3.7/runpy.py", line 263, in run_path
  File "/umbc/xfs1/jianwu/common/anaconda3/lib/python3.7/runpy.py", line 96, in _run_module_code
  File "/umbc/xfs1/jianwu/common/anaconda3/lib/python3.7/runpy.py", line 85, in _run_code
  File "/umbc/xfs1/jianwu/common/MODIS_Aggregation/savioexe/test/4/t1/1m4ndk1.py", line 8, in <module>
  File "/umbc/xfs1/jianwu/common/anaconda3/lib/python3.7/site-packages/numpy/__init__.py", line 158, in <module>
  File "<frozen importlib._bootstrap>", line 983, in _find_and_load
  File "<frozen importlib._bootstrap>", line 967, in _find_and_load_unlocked
  File "<frozen importlib._bootstrap>", line 677, in _load_unlocked
  File "<frozen importlib._bootstrap_external>", line 724, in exec_module
  File "<frozen importlib._bootstrap_external>", line 859, in get_code
  File "<frozen importlib._bootstrap_external>", line 916, in get_data
OSError: [Errno 23] Too many open files in system: '/umbc/xfs1/jianwu/common/anaconda3/lib/python3.7/site-packages/numpy/fft/__init__.py'
Traceback (most recent call last):
  File "/umbc/xfs1/jianwu/common/anaconda3/lib/python3.7/multiprocessing/forkserver.py", line 261, in main
  File "/umbc/xfs1/jianwu/common/anaconda3/lib/python3.7/multiprocessing/forkserver.py", line 297, in _serve_one
  File "/umbc/xfs1/jianwu/common/anaconda3/lib/python3.7/multiprocessing/spawn.py", line 114, in _main
  File "/umbc/xfs1/jianwu/common/anaconda3/lib/python3.7/multiprocessing/spawn.py", line 225, in prepare
  File "/umbc/xfs1/jianwu/common/anaconda3/lib/python3.7/multiprocessing/spawn.py", line 277, in _fixup_main_from_path
  File "/umbc/xfs1/jianwu/common/anaconda3/lib/python3.7/runpy.py", line 263, in run_path
  File "/umbc/xfs1/jianwu/common/anaconda3/lib/python3.7/runpy.py", line 96, in _run_module_code
  File "/umbc/xfs1/jianwu/common/anaconda3/lib/python3.7/runpy.py", line 85, in _run_code
  File "/umbc/xfs1/jianwu/common/MODIS_Aggregation/savioexe/test/4/t1/1m4ndk1.py", line 8, in <module>
  File "/umbc/xfs1/jianwu/common/anaconda3/lib/python3.7/site-packages/numpy/__init__.py", line 158, in <module>
  File "<frozen importlib._bootstrap>", line 983, in _find_and_load
  File "<frozen importlib._bootstrap>", line 967, in _find_and_load_unlocked
  File "<frozen importlib._bootstrap>", line 677, in _load_unlocked
  File "<frozen importlib._bootstrap_external>", line 724, in exec_module
  File "<frozen importlib._bootstrap_external>", line 859, in get_code
  File "<frozen importlib._bootstrap_external>", line 916, in get_data
OSError: [Errno 23] Too many open files in system: '/umbc/xfs1/jianwu/common/anaconda3/lib/python3.7/site-packages/numpy/fft/__init__.py'
Traceback (most recent call last):
  File "/umbc/xfs1/jianwu/common/anaconda3/lib/python3.7/multiprocessing/forkserver.py", line 261, in main
  File "/umbc/xfs1/jianwu/common/anaconda3/lib/python3.7/multiprocessing/forkserver.py", line 297, in _serve_one
  File "/umbc/xfs1/jianwu/common/anaconda3/lib/python3.7/multiprocessing/spawn.py", line 114, in _main
  File "/umbc/xfs1/jianwu/common/anaconda3/lib/python3.7/multiprocessing/spawn.py", line 225, in prepare
  File "/umbc/xfs1/jianwu/common/anaconda3/lib/python3.7/multiprocessing/spawn.py", line 277, in _fixup_main_from_path
  File "/umbc/xfs1/jianwu/common/anaconda3/lib/python3.7/runpy.py", line 263, in run_path
  File "/umbc/xfs1/jianwu/common/anaconda3/lib/python3.7/runpy.py", line 96, in _run_module_code
  File "/umbc/xfs1/jianwu/common/anaconda3/lib/python3.7/runpy.py", line 85, in _run_code
  File "/umbc/xfs1/jianwu/common/MODIS_Aggregation/savioexe/test/4/t1/1m4ndk1.py", line 8, in <module>
  File "/umbc/xfs1/jianwu/common/anaconda3/lib/python3.7/site-packages/numpy/__init__.py", line 158, in <module>
  File "<frozen importlib._bootstrap>", line 983, in _find_and_load
  File "<frozen importlib._bootstrap>", line 967, in _find_and_load_unlocked
  File "<frozen importlib._bootstrap>", line 677, in _load_unlocked
  File "<frozen importlib._bootstrap_external>", line 724, in exec_module
  File "<frozen importlib._bootstrap_external>", line 859, in get_code
  File "<frozen importlib._bootstrap_external>", line 916, in get_data
OSError: [Errno 23] Too many open files in system: '/umbc/xfs1/jianwu/common/anaconda3/lib/python3.7/site-packages/numpy/fft/__init__.py'
Traceback (most recent call last):
  File "/umbc/xfs1/jianwu/common/anaconda3/lib/python3.7/multiprocessing/forkserver.py", line 261, in main
  File "/umbc/xfs1/jianwu/common/anaconda3/lib/python3.7/multiprocessing/forkserver.py", line 297, in _serve_one
  File "/umbc/xfs1/jianwu/common/anaconda3/lib/python3.7/multiprocessing/spawn.py", line 114, in _main
  File "/umbc/xfs1/jianwu/common/anaconda3/lib/python3.7/multiprocessing/spawn.py", line 225, in prepare
  File "/umbc/xfs1/jianwu/common/anaconda3/lib/python3.7/multiprocessing/spawn.py", line 277, in _fixup_main_from_path
  File "/umbc/xfs1/jianwu/common/anaconda3/lib/python3.7/runpy.py", line 263, in run_path
  File "/umbc/xfs1/jianwu/common/anaconda3/lib/python3.7/runpy.py", line 96, in _run_module_code
  File "/umbc/xfs1/jianwu/common/anaconda3/lib/python3.7/runpy.py", line 85, in _run_code
  File "/umbc/xfs1/jianwu/common/MODIS_Aggregation/savioexe/test/4/t1/1m4ndk1.py", line 8, in <module>
  File "/umbc/xfs1/jianwu/common/anaconda3/lib/python3.7/site-packages/numpy/__init__.py", line 158, in <module>
  File "<frozen importlib._bootstrap>", line 983, in _find_and_load
  File "<frozen importlib._bootstrap>", line 967, in _find_and_load_unlocked
  File "<frozen importlib._bootstrap>", line 677, in _load_unlocked
  File "<frozen importlib._bootstrap_external>", line 724, in exec_module
  File "<frozen importlib._bootstrap_external>", line 859, in get_code
  File "<frozen importlib._bootstrap_external>", line 916, in get_data
OSError: [Errno 23] Too many open files in system: '/umbc/xfs1/jianwu/common/anaconda3/lib/python3.7/site-packages/numpy/fft/__init__.py'
Traceback (most recent call last):
  File "/umbc/xfs1/jianwu/common/anaconda3/lib/python3.7/multiprocessing/forkserver.py", line 261, in main
  File "/umbc/xfs1/jianwu/common/anaconda3/lib/python3.7/multiprocessing/forkserver.py", line 297, in _serve_one
  File "/umbc/xfs1/jianwu/common/anaconda3/lib/python3.7/multiprocessing/spawn.py", line 114, in _main
  File "/umbc/xfs1/jianwu/common/anaconda3/lib/python3.7/multiprocessing/spawn.py", line 225, in prepare
  File "/umbc/xfs1/jianwu/common/anaconda3/lib/python3.7/multiprocessing/spawn.py", line 277, in _fixup_main_from_path
  File "/umbc/xfs1/jianwu/common/anaconda3/lib/python3.7/runpy.py", line 263, in run_path
  File "/umbc/xfs1/jianwu/common/anaconda3/lib/python3.7/runpy.py", line 96, in _run_module_code
  File "/umbc/xfs1/jianwu/common/anaconda3/lib/python3.7/runpy.py", line 85, in _run_code
  File "/umbc/xfs1/jianwu/common/MODIS_Aggregation/savioexe/test/4/t1/1m4ndk1.py", line 8, in <module>
  File "/umbc/xfs1/jianwu/common/anaconda3/lib/python3.7/site-packages/numpy/__init__.py", line 158, in <module>
  File "<frozen importlib._bootstrap>", line 983, in _find_and_load
  File "<frozen importlib._bootstrap>", line 967, in _find_and_load_unlocked
  File "<frozen importlib._bootstrap>", line 677, in _load_unlocked
  File "<frozen importlib._bootstrap_external>", line 724, in exec_module
  File "<frozen importlib._bootstrap_external>", line 859, in get_code
  File "<frozen importlib._bootstrap_external>", line 916, in get_data
OSError: [Errno 23] Too many open files in system: '/umbc/xfs1/jianwu/common/anaconda3/lib/python3.7/site-packages/numpy/fft/__init__.py'
Traceback (most recent call last):
  File "/umbc/xfs1/jianwu/common/anaconda3/lib/python3.7/multiprocessing/forkserver.py", line 261, in main
  File "/umbc/xfs1/jianwu/common/anaconda3/lib/python3.7/multiprocessing/forkserver.py", line 297, in _serve_one
  File "/umbc/xfs1/jianwu/common/anaconda3/lib/python3.7/multiprocessing/spawn.py", line 114, in _main
  File "/umbc/xfs1/jianwu/common/anaconda3/lib/python3.7/multiprocessing/spawn.py", line 225, in prepare
  File "/umbc/xfs1/jianwu/common/anaconda3/lib/python3.7/multiprocessing/spawn.py", line 277, in _fixup_main_from_path
  File "/umbc/xfs1/jianwu/common/anaconda3/lib/python3.7/runpy.py", line 263, in run_path
  File "/umbc/xfs1/jianwu/common/anaconda3/lib/python3.7/runpy.py", line 96, in _run_module_code
  File "/umbc/xfs1/jianwu/common/anaconda3/lib/python3.7/runpy.py", line 85, in _run_code
  File "/umbc/xfs1/jianwu/common/MODIS_Aggregation/savioexe/test/4/t1/1m4ndk1.py", line 8, in <module>
  File "/umbc/xfs1/jianwu/common/anaconda3/lib/python3.7/site-packages/numpy/__init__.py", line 158, in <module>
  File "<frozen importlib._bootstrap>", line 983, in _find_and_load
  File "<frozen importlib._bootstrap>", line 967, in _find_and_load_unlocked
  File "<frozen importlib._bootstrap>", line 677, in _load_unlocked
  File "<frozen importlib._bootstrap_external>", line 724, in exec_module
  File "<frozen importlib._bootstrap_external>", line 859, in get_code
  File "<frozen importlib._bootstrap_external>", line 916, in get_data
OSError: [Errno 23] Too many open files in system: '/umbc/xfs1/jianwu/common/anaconda3/lib/python3.7/site-packages/numpy/fft/__init__.py'
Traceback (most recent call last):
  File "/umbc/xfs1/jianwu/common/anaconda3/lib/python3.7/multiprocessing/forkserver.py", line 261, in main
  File "/umbc/xfs1/jianwu/common/anaconda3/lib/python3.7/multiprocessing/forkserver.py", line 297, in _serve_one
  File "/umbc/xfs1/jianwu/common/anaconda3/lib/python3.7/multiprocessing/spawn.py", line 114, in _main
  File "/umbc/xfs1/jianwu/common/anaconda3/lib/python3.7/multiprocessing/spawn.py", line 225, in prepare
  File "/umbc/xfs1/jianwu/common/anaconda3/lib/python3.7/multiprocessing/spawn.py", line 277, in _fixup_main_from_path
  File "/umbc/xfs1/jianwu/common/anaconda3/lib/python3.7/runpy.py", line 263, in run_path
  File "/umbc/xfs1/jianwu/common/anaconda3/lib/python3.7/runpy.py", line 96, in _run_module_code
  File "/umbc/xfs1/jianwu/common/anaconda3/lib/python3.7/runpy.py", line 85, in _run_code
  File "/umbc/xfs1/jianwu/common/MODIS_Aggregation/savioexe/test/4/t1/1m4ndk1.py", line 8, in <module>
  File "/umbc/xfs1/jianwu/common/anaconda3/lib/python3.7/site-packages/numpy/__init__.py", line 158, in <module>
  File "<frozen importlib._bootstrap>", line 983, in _find_and_load
  File "<frozen importlib._bootstrap>", line 967, in _find_and_load_unlocked
  File "<frozen importlib._bootstrap>", line 677, in _load_unlocked
  File "<frozen importlib._bootstrap_external>", line 724, in exec_module
  File "<frozen importlib._bootstrap_external>", line 859, in get_code
  File "<frozen importlib._bootstrap_external>", line 916, in get_data
OSError: [Errno 23] Too many open files in system: '/umbc/xfs1/jianwu/common/anaconda3/lib/python3.7/site-packages/numpy/fft/__init__.py'
Traceback (most recent call last):
  File "/umbc/xfs1/jianwu/common/anaconda3/lib/python3.7/multiprocessing/forkserver.py", line 261, in main
  File "/umbc/xfs1/jianwu/common/anaconda3/lib/python3.7/multiprocessing/forkserver.py", line 297, in _serve_one
  File "/umbc/xfs1/jianwu/common/anaconda3/lib/python3.7/multiprocessing/spawn.py", line 114, in _main
  File "/umbc/xfs1/jianwu/common/anaconda3/lib/python3.7/multiprocessing/spawn.py", line 225, in prepare
  File "/umbc/xfs1/jianwu/common/anaconda3/lib/python3.7/multiprocessing/spawn.py", line 277, in _fixup_main_from_path
  File "/umbc/xfs1/jianwu/common/anaconda3/lib/python3.7/runpy.py", line 263, in run_path
  File "/umbc/xfs1/jianwu/common/anaconda3/lib/python3.7/runpy.py", line 96, in _run_module_code
  File "/umbc/xfs1/jianwu/common/anaconda3/lib/python3.7/runpy.py", line 85, in _run_code
  File "/umbc/xfs1/jianwu/common/MODIS_Aggregation/savioexe/test/4/t1/1m4ndk1.py", line 8, in <module>
  File "/umbc/xfs1/jianwu/common/anaconda3/lib/python3.7/site-packages/numpy/__init__.py", line 158, in <module>
  File "<frozen importlib._bootstrap>", line 983, in _find_and_load
  File "<frozen importlib._bootstrap>", line 967, in _find_and_load_unlocked
  File "<frozen importlib._bootstrap>", line 677, in _load_unlocked
  File "<frozen importlib._bootstrap_external>", line 724, in exec_module
  File "<frozen importlib._bootstrap_external>", line 859, in get_code
  File "<frozen importlib._bootstrap_external>", line 916, in get_data
OSError: [Errno 23] Too many open files in system: '/umbc/xfs1/jianwu/common/anaconda3/lib/python3.7/site-packages/numpy/fft/__init__.py'
distributed.scheduler - ERROR - Error in reevaluate occupancy
Traceback (most recent call last):
  File "/umbc/xfs1/jianwu/common/anaconda3/lib/python3.7/site-packages/distributed/scheduler.py", line 4290, in reevaluate_occupancy
    if self.proc.cpu_percent() < 50:
  File "/umbc/xfs1/jianwu/common/anaconda3/lib/python3.7/site-packages/psutil/__init__.py", line 987, in cpu_percent
    pt2 = self._proc.cpu_times()
  File "/umbc/xfs1/jianwu/common/anaconda3/lib/python3.7/site-packages/psutil/_pslinux.py", line 1508, in wrapper
    return fun(self, *args, **kwargs)
  File "/umbc/xfs1/jianwu/common/anaconda3/lib/python3.7/site-packages/psutil/_pslinux.py", line 1681, in cpu_times
    values = self._parse_stat_file()
  File "/umbc/xfs1/jianwu/common/anaconda3/lib/python3.7/site-packages/psutil/_common.py", line 340, in wrapper
    return fun(self)
  File "/umbc/xfs1/jianwu/common/anaconda3/lib/python3.7/site-packages/psutil/_pslinux.py", line 1547, in _parse_stat_file
    with open_binary("%s/%s/stat" % (self._procfs_path, self.pid)) as f:
  File "/umbc/xfs1/jianwu/common/anaconda3/lib/python3.7/site-packages/psutil/_common.py", line 582, in open_binary
    return open(fname, "rb", **kwargs)
OSError: [Errno 23] Too many open files in system: '/proc/279585/stat'
tornado.application - ERROR - Exception in callback functools.partial(<function wrap.<locals>.null_wrapper at 0x2aab07f02950>, worker_index=0)
Traceback (most recent call last):
  File "/umbc/xfs1/jianwu/common/anaconda3/lib/python3.7/site-packages/tornado/ioloop.py", line 758, in _run_callback
    ret = callback()
  File "/umbc/xfs1/jianwu/common/anaconda3/lib/python3.7/site-packages/tornado/stack_context.py", line 300, in null_wrapper
    return fn(*args, **kwargs)
  File "/umbc/xfs1/jianwu/common/anaconda3/lib/python3.7/site-packages/distributed/scheduler.py", line 4290, in reevaluate_occupancy
    if self.proc.cpu_percent() < 50:
  File "/umbc/xfs1/jianwu/common/anaconda3/lib/python3.7/site-packages/psutil/__init__.py", line 987, in cpu_percent
    pt2 = self._proc.cpu_times()
  File "/umbc/xfs1/jianwu/common/anaconda3/lib/python3.7/site-packages/psutil/_pslinux.py", line 1508, in wrapper
    return fun(self, *args, **kwargs)
  File "/umbc/xfs1/jianwu/common/anaconda3/lib/python3.7/site-packages/psutil/_pslinux.py", line 1681, in cpu_times
    values = self._parse_stat_file()
  File "/umbc/xfs1/jianwu/common/anaconda3/lib/python3.7/site-packages/psutil/_common.py", line 340, in wrapper
    return fun(self)
  File "/umbc/xfs1/jianwu/common/anaconda3/lib/python3.7/site-packages/psutil/_pslinux.py", line 1547, in _parse_stat_file
    with open_binary("%s/%s/stat" % (self._procfs_path, self.pid)) as f:
  File "/umbc/xfs1/jianwu/common/anaconda3/lib/python3.7/site-packages/psutil/_common.py", line 582, in open_binary
    return open(fname, "rb", **kwargs)
OSError: [Errno 23] Too many open files in system: '/proc/279585/stat'
distributed.nanny - WARNING - Worker process 279723 exited with status 1
tornado.application - ERROR - Exception in callback functools.partial(<function wrap.<locals>.null_wrapper at 0x2aab07f02a60>, worker_index=0)
Traceback (most recent call last):
  File "/umbc/xfs1/jianwu/common/anaconda3/lib/python3.7/site-packages/tornado/ioloop.py", line 758, in _run_callback
    ret = callback()
  File "/umbc/xfs1/jianwu/common/anaconda3/lib/python3.7/site-packages/tornado/stack_context.py", line 300, in null_wrapper
    return fn(*args, **kwargs)
  File "/umbc/xfs1/jianwu/common/anaconda3/lib/python3.7/site-packages/distributed/scheduler.py", line 4290, in reevaluate_occupancy
    if self.proc.cpu_percent() < 50:
  File "/umbc/xfs1/jianwu/common/anaconda3/lib/python3.7/site-packages/psutil/__init__.py", line 987, in cpu_percent
    pt2 = self._proc.cpu_times()
  File "/umbc/xfs1/jianwu/common/anaconda3/lib/python3.7/site-packages/psutil/_pslinux.py", line 1508, in wrapper
    return fun(self, *args, **kwargs)
  File "/umbc/xfs1/jianwu/common/anaconda3/lib/python3.7/site-packages/psutil/_pslinux.py", line 1681, in cpu_times
    values = self._parse_stat_file()
  File "/umbc/xfs1/jianwu/common/anaconda3/lib/python3.7/site-packages/psutil/_common.py", line 340, in wrapper
    return fun(self)
  File "/umbc/xfs1/jianwu/common/anaconda3/lib/python3.7/site-packages/psutil/_pslinux.py", line 1547, in _parse_stat_file
    with open_binary("%s/%s/stat" % (self._procfs_path, self.pid)) as f:
  File "/umbc/xfs1/jianwu/common/anaconda3/lib/python3.7/site-packages/psutil/_common.py", line 582, in open_binary
    return open(fname, "rb", **kwargs)
OSError: [Errno 23] Too many open files in system: '/proc/279585/stat'
distributed.nanny - WARNING - Worker process 279685 exited with status 1
distributed.nanny - WARNING - Worker process 279702 exited with status 1
distributed.nanny - WARNING - Worker process 279700 exited with status 1
distributed.nanny - WARNING - Worker process 279680 exited with status 1
distributed.nanny - WARNING - Worker process 279706 exited with status 1
distributed.nanny - WARNING - Worker process 279741 exited with status 1
distributed.nanny - WARNING - Worker process 279740 exited with status 1
distributed.nanny - WARNING - Worker process 279737 exited with status 1
distributed.nanny - WARNING - Worker process 279718 exited with status 1
distributed.nanny - WARNING - Worker process 279691 exited with status 1
distributed.nanny - WARNING - Worker process 279701 exited with status 1
distributed.nanny - WARNING - Worker process 279732 exited with status 1
distributed.nanny - WARNING - Worker process 279734 exited with status 1
distributed.nanny - WARNING - Worker process 279731 exited with status 1
distributed.nanny - WARNING - Worker process 279710 exited with status 1
distributed.nanny - WARNING - Worker process 279694 exited with status 1
distributed.nanny - WARNING - Worker process 279684 exited with status 1
distributed.nanny - WARNING - Worker process 279747 exited with status 1
distributed.nanny - WARNING - Worker process 279687 exited with status 1
distributed.nanny - WARNING - Worker process 279693 exited with status 1
distributed.nanny - WARNING - Worker process 279721 exited with status 1
distributed.nanny - WARNING - Worker process 279743 exited with status 1
distributed.nanny - WARNING - Worker process 279699 exited with status 1
distributed.nanny - WARNING - Worker process 279679 exited with status 1
distributed.nanny - WARNING - Worker process 279695 exited with status 1
distributed.nanny - WARNING - Worker process 279713 exited with status 1
distributed.nanny - WARNING - Worker process 279739 exited with status 1
distributed.nanny - WARNING - Worker process 279722 exited with status 1
distributed.nanny - WARNING - Worker process 279728 exited with status 1
distributed.nanny - WARNING - Worker process 279708 exited with status 1
distributed.nanny - WARNING - Worker process 279682 exited with status 1
distributed.nanny - WARNING - Worker process 279711 exited with status 1
distributed.nanny - WARNING - Worker process 279725 exited with status 1
distributed.nanny - WARNING - Worker process 279749 exited with status 1
distributed.nanny - WARNING - Worker process 279717 exited with status 1
tornado.application - ERROR - Multiple exceptions in yield list
Traceback (most recent call last):
  File "/umbc/xfs1/jianwu/common/anaconda3/lib/python3.7/site-packages/tornado/gen.py", line 883, in callback
    result_list.append(f.result())
  File "/umbc/xfs1/jianwu/common/anaconda3/lib/python3.7/site-packages/tornado/gen.py", line 1147, in run
    yielded = self.gen.send(value)
  File "/umbc/xfs1/jianwu/common/anaconda3/lib/python3.7/site-packages/distributed/deploy/local.py", line 217, in _start_worker
    raise gen.TimeoutError("Worker failed to start")
tornado.util.TimeoutError: Worker failed to start
tornado.application - ERROR - Multiple exceptions in yield list
Traceback (most recent call last):
  File "/umbc/xfs1/jianwu/common/anaconda3/lib/python3.7/site-packages/tornado/gen.py", line 883, in callback
    result_list.append(f.result())
  File "/umbc/xfs1/jianwu/common/anaconda3/lib/python3.7/site-packages/tornado/gen.py", line 1147, in run
    yielded = self.gen.send(value)
  File "/umbc/xfs1/jianwu/common/anaconda3/lib/python3.7/site-packages/distributed/deploy/local.py", line 217, in _start_worker
    raise gen.TimeoutError("Worker failed to start")
tornado.util.TimeoutError: Worker failed to start
tornado.application - ERROR - Multiple exceptions in yield list
Traceback (most recent call last):
  File "/umbc/xfs1/jianwu/common/anaconda3/lib/python3.7/site-packages/tornado/gen.py", line 883, in callback
    result_list.append(f.result())
  File "/umbc/xfs1/jianwu/common/anaconda3/lib/python3.7/site-packages/tornado/gen.py", line 1147, in run
    yielded = self.gen.send(value)
  File "/umbc/xfs1/jianwu/common/anaconda3/lib/python3.7/site-packages/distributed/deploy/local.py", line 217, in _start_worker
    raise gen.TimeoutError("Worker failed to start")
tornado.util.TimeoutError: Worker failed to start
tornado.application - ERROR - Multiple exceptions in yield list
Traceback (most recent call last):
  File "/umbc/xfs1/jianwu/common/anaconda3/lib/python3.7/site-packages/tornado/gen.py", line 883, in callback
    result_list.append(f.result())
  File "/umbc/xfs1/jianwu/common/anaconda3/lib/python3.7/site-packages/tornado/gen.py", line 1147, in run
    yielded = self.gen.send(value)
  File "/umbc/xfs1/jianwu/common/anaconda3/lib/python3.7/site-packages/distributed/deploy/local.py", line 217, in _start_worker
    raise gen.TimeoutError("Worker failed to start")
tornado.util.TimeoutError: Worker failed to start
tornado.application - ERROR - Multiple exceptions in yield list
Traceback (most recent call last):
  File "/umbc/xfs1/jianwu/common/anaconda3/lib/python3.7/site-packages/tornado/gen.py", line 883, in callback
    result_list.append(f.result())
  File "/umbc/xfs1/jianwu/common/anaconda3/lib/python3.7/site-packages/tornado/gen.py", line 1147, in run
    yielded = self.gen.send(value)
  File "/umbc/xfs1/jianwu/common/anaconda3/lib/python3.7/site-packages/distributed/deploy/local.py", line 217, in _start_worker
    raise gen.TimeoutError("Worker failed to start")
tornado.util.TimeoutError: Worker failed to start
tornado.application - ERROR - Multiple exceptions in yield list
Traceback (most recent call last):
  File "/umbc/xfs1/jianwu/common/anaconda3/lib/python3.7/site-packages/tornado/gen.py", line 883, in callback
    result_list.append(f.result())
  File "/umbc/xfs1/jianwu/common/anaconda3/lib/python3.7/site-packages/tornado/gen.py", line 1147, in run
    yielded = self.gen.send(value)
  File "/umbc/xfs1/jianwu/common/anaconda3/lib/python3.7/site-packages/distributed/deploy/local.py", line 217, in _start_worker
    raise gen.TimeoutError("Worker failed to start")
tornado.util.TimeoutError: Worker failed to start
tornado.application - ERROR - Multiple exceptions in yield list
Traceback (most recent call last):
  File "/umbc/xfs1/jianwu/common/anaconda3/lib/python3.7/site-packages/tornado/gen.py", line 883, in callback
    result_list.append(f.result())
  File "/umbc/xfs1/jianwu/common/anaconda3/lib/python3.7/site-packages/tornado/gen.py", line 1147, in run
    yielded = self.gen.send(value)
  File "/umbc/xfs1/jianwu/common/anaconda3/lib/python3.7/site-packages/distributed/deploy/local.py", line 217, in _start_worker
    raise gen.TimeoutError("Worker failed to start")
tornado.util.TimeoutError: Worker failed to start
tornado.application - ERROR - Multiple exceptions in yield list
Traceback (most recent call last):
  File "/umbc/xfs1/jianwu/common/anaconda3/lib/python3.7/site-packages/tornado/gen.py", line 883, in callback
    result_list.append(f.result())
  File "/umbc/xfs1/jianwu/common/anaconda3/lib/python3.7/site-packages/tornado/gen.py", line 1147, in run
    yielded = self.gen.send(value)
  File "/umbc/xfs1/jianwu/common/anaconda3/lib/python3.7/site-packages/distributed/deploy/local.py", line 217, in _start_worker
    raise gen.TimeoutError("Worker failed to start")
tornado.util.TimeoutError: Worker failed to start
tornado.application - ERROR - Multiple exceptions in yield list
Traceback (most recent call last):
  File "/umbc/xfs1/jianwu/common/anaconda3/lib/python3.7/site-packages/tornado/gen.py", line 883, in callback
    result_list.append(f.result())
  File "/umbc/xfs1/jianwu/common/anaconda3/lib/python3.7/site-packages/tornado/gen.py", line 1147, in run
    yielded = self.gen.send(value)
  File "/umbc/xfs1/jianwu/common/anaconda3/lib/python3.7/site-packages/distributed/deploy/local.py", line 217, in _start_worker
    raise gen.TimeoutError("Worker failed to start")
tornado.util.TimeoutError: Worker failed to start
tornado.application - ERROR - Multiple exceptions in yield list
Traceback (most recent call last):
  File "/umbc/xfs1/jianwu/common/anaconda3/lib/python3.7/site-packages/tornado/gen.py", line 883, in callback
    result_list.append(f.result())
  File "/umbc/xfs1/jianwu/common/anaconda3/lib/python3.7/site-packages/tornado/gen.py", line 1147, in run
    yielded = self.gen.send(value)
  File "/umbc/xfs1/jianwu/common/anaconda3/lib/python3.7/site-packages/distributed/deploy/local.py", line 217, in _start_worker
    raise gen.TimeoutError("Worker failed to start")
tornado.util.TimeoutError: Worker failed to start
tornado.application - ERROR - Multiple exceptions in yield list
Traceback (most recent call last):
  File "/umbc/xfs1/jianwu/common/anaconda3/lib/python3.7/site-packages/tornado/gen.py", line 883, in callback
    result_list.append(f.result())
  File "/umbc/xfs1/jianwu/common/anaconda3/lib/python3.7/site-packages/tornado/gen.py", line 1147, in run
    yielded = self.gen.send(value)
  File "/umbc/xfs1/jianwu/common/anaconda3/lib/python3.7/site-packages/distributed/deploy/local.py", line 217, in _start_worker
    raise gen.TimeoutError("Worker failed to start")
tornado.util.TimeoutError: Worker failed to start
tornado.application - ERROR - Multiple exceptions in yield list
Traceback (most recent call last):
  File "/umbc/xfs1/jianwu/common/anaconda3/lib/python3.7/site-packages/tornado/gen.py", line 883, in callback
    result_list.append(f.result())
  File "/umbc/xfs1/jianwu/common/anaconda3/lib/python3.7/site-packages/tornado/gen.py", line 1147, in run
    yielded = self.gen.send(value)
  File "/umbc/xfs1/jianwu/common/anaconda3/lib/python3.7/site-packages/distributed/deploy/local.py", line 217, in _start_worker
    raise gen.TimeoutError("Worker failed to start")
tornado.util.TimeoutError: Worker failed to start
tornado.application - ERROR - Multiple exceptions in yield list
Traceback (most recent call last):
  File "/umbc/xfs1/jianwu/common/anaconda3/lib/python3.7/site-packages/tornado/gen.py", line 883, in callback
    result_list.append(f.result())
  File "/umbc/xfs1/jianwu/common/anaconda3/lib/python3.7/site-packages/tornado/gen.py", line 1147, in run
    yielded = self.gen.send(value)
  File "/umbc/xfs1/jianwu/common/anaconda3/lib/python3.7/site-packages/distributed/deploy/local.py", line 217, in _start_worker
    raise gen.TimeoutError("Worker failed to start")
tornado.util.TimeoutError: Worker failed to start
tornado.application - ERROR - Multiple exceptions in yield list
Traceback (most recent call last):
  File "/umbc/xfs1/jianwu/common/anaconda3/lib/python3.7/site-packages/tornado/gen.py", line 883, in callback
    result_list.append(f.result())
  File "/umbc/xfs1/jianwu/common/anaconda3/lib/python3.7/site-packages/tornado/gen.py", line 1147, in run
    yielded = self.gen.send(value)
  File "/umbc/xfs1/jianwu/common/anaconda3/lib/python3.7/site-packages/distributed/deploy/local.py", line 217, in _start_worker
    raise gen.TimeoutError("Worker failed to start")
tornado.util.TimeoutError: Worker failed to start
tornado.application - ERROR - Multiple exceptions in yield list
Traceback (most recent call last):
  File "/umbc/xfs1/jianwu/common/anaconda3/lib/python3.7/site-packages/tornado/gen.py", line 883, in callback
    result_list.append(f.result())
  File "/umbc/xfs1/jianwu/common/anaconda3/lib/python3.7/site-packages/tornado/gen.py", line 1147, in run
    yielded = self.gen.send(value)
  File "/umbc/xfs1/jianwu/common/anaconda3/lib/python3.7/site-packages/distributed/deploy/local.py", line 217, in _start_worker
    raise gen.TimeoutError("Worker failed to start")
tornado.util.TimeoutError: Worker failed to start
tornado.application - ERROR - Multiple exceptions in yield list
Traceback (most recent call last):
  File "/umbc/xfs1/jianwu/common/anaconda3/lib/python3.7/site-packages/tornado/gen.py", line 883, in callback
    result_list.append(f.result())
  File "/umbc/xfs1/jianwu/common/anaconda3/lib/python3.7/site-packages/tornado/gen.py", line 1147, in run
    yielded = self.gen.send(value)
  File "/umbc/xfs1/jianwu/common/anaconda3/lib/python3.7/site-packages/distributed/deploy/local.py", line 217, in _start_worker
    raise gen.TimeoutError("Worker failed to start")
tornado.util.TimeoutError: Worker failed to start
tornado.application - ERROR - Multiple exceptions in yield list
Traceback (most recent call last):
  File "/umbc/xfs1/jianwu/common/anaconda3/lib/python3.7/site-packages/tornado/gen.py", line 883, in callback
    result_list.append(f.result())
  File "/umbc/xfs1/jianwu/common/anaconda3/lib/python3.7/site-packages/tornado/gen.py", line 1147, in run
    yielded = self.gen.send(value)
  File "/umbc/xfs1/jianwu/common/anaconda3/lib/python3.7/site-packages/distributed/deploy/local.py", line 217, in _start_worker
    raise gen.TimeoutError("Worker failed to start")
tornado.util.TimeoutError: Worker failed to start
tornado.application - ERROR - Multiple exceptions in yield list
Traceback (most recent call last):
  File "/umbc/xfs1/jianwu/common/anaconda3/lib/python3.7/site-packages/tornado/gen.py", line 883, in callback
    result_list.append(f.result())
  File "/umbc/xfs1/jianwu/common/anaconda3/lib/python3.7/site-packages/tornado/gen.py", line 1147, in run
    yielded = self.gen.send(value)
  File "/umbc/xfs1/jianwu/common/anaconda3/lib/python3.7/site-packages/distributed/deploy/local.py", line 217, in _start_worker
    raise gen.TimeoutError("Worker failed to start")
tornado.util.TimeoutError: Worker failed to start
tornado.application - ERROR - Multiple exceptions in yield list
Traceback (most recent call last):
  File "/umbc/xfs1/jianwu/common/anaconda3/lib/python3.7/site-packages/tornado/gen.py", line 883, in callback
    result_list.append(f.result())
  File "/umbc/xfs1/jianwu/common/anaconda3/lib/python3.7/site-packages/tornado/gen.py", line 1147, in run
    yielded = self.gen.send(value)
  File "/umbc/xfs1/jianwu/common/anaconda3/lib/python3.7/site-packages/distributed/deploy/local.py", line 217, in _start_worker
    raise gen.TimeoutError("Worker failed to start")
tornado.util.TimeoutError: Worker failed to start
tornado.application - ERROR - Multiple exceptions in yield list
Traceback (most recent call last):
  File "/umbc/xfs1/jianwu/common/anaconda3/lib/python3.7/site-packages/tornado/gen.py", line 883, in callback
    result_list.append(f.result())
  File "/umbc/xfs1/jianwu/common/anaconda3/lib/python3.7/site-packages/tornado/gen.py", line 1147, in run
    yielded = self.gen.send(value)
  File "/umbc/xfs1/jianwu/common/anaconda3/lib/python3.7/site-packages/distributed/deploy/local.py", line 217, in _start_worker
    raise gen.TimeoutError("Worker failed to start")
tornado.util.TimeoutError: Worker failed to start
tornado.application - ERROR - Multiple exceptions in yield list
Traceback (most recent call last):
  File "/umbc/xfs1/jianwu/common/anaconda3/lib/python3.7/site-packages/tornado/gen.py", line 883, in callback
    result_list.append(f.result())
  File "/umbc/xfs1/jianwu/common/anaconda3/lib/python3.7/site-packages/tornado/gen.py", line 1147, in run
    yielded = self.gen.send(value)
  File "/umbc/xfs1/jianwu/common/anaconda3/lib/python3.7/site-packages/distributed/deploy/local.py", line 217, in _start_worker
    raise gen.TimeoutError("Worker failed to start")
tornado.util.TimeoutError: Worker failed to start
tornado.application - ERROR - Multiple exceptions in yield list
Traceback (most recent call last):
  File "/umbc/xfs1/jianwu/common/anaconda3/lib/python3.7/site-packages/tornado/gen.py", line 883, in callback
    result_list.append(f.result())
  File "/umbc/xfs1/jianwu/common/anaconda3/lib/python3.7/site-packages/tornado/gen.py", line 1147, in run
    yielded = self.gen.send(value)
  File "/umbc/xfs1/jianwu/common/anaconda3/lib/python3.7/site-packages/distributed/deploy/local.py", line 217, in _start_worker
    raise gen.TimeoutError("Worker failed to start")
tornado.util.TimeoutError: Worker failed to start
tornado.application - ERROR - Multiple exceptions in yield list
Traceback (most recent call last):
  File "/umbc/xfs1/jianwu/common/anaconda3/lib/python3.7/site-packages/tornado/gen.py", line 883, in callback
    result_list.append(f.result())
  File "/umbc/xfs1/jianwu/common/anaconda3/lib/python3.7/site-packages/tornado/gen.py", line 1147, in run
    yielded = self.gen.send(value)
  File "/umbc/xfs1/jianwu/common/anaconda3/lib/python3.7/site-packages/distributed/deploy/local.py", line 217, in _start_worker
    raise gen.TimeoutError("Worker failed to start")
tornado.util.TimeoutError: Worker failed to start
tornado.application - ERROR - Multiple exceptions in yield list
Traceback (most recent call last):
  File "/umbc/xfs1/jianwu/common/anaconda3/lib/python3.7/site-packages/tornado/gen.py", line 883, in callback
    result_list.append(f.result())
  File "/umbc/xfs1/jianwu/common/anaconda3/lib/python3.7/site-packages/tornado/gen.py", line 1147, in run
    yielded = self.gen.send(value)
  File "/umbc/xfs1/jianwu/common/anaconda3/lib/python3.7/site-packages/distributed/deploy/local.py", line 217, in _start_worker
    raise gen.TimeoutError("Worker failed to start")
tornado.util.TimeoutError: Worker failed to start
tornado.application - ERROR - Multiple exceptions in yield list
Traceback (most recent call last):
  File "/umbc/xfs1/jianwu/common/anaconda3/lib/python3.7/site-packages/tornado/gen.py", line 883, in callback
    result_list.append(f.result())
  File "/umbc/xfs1/jianwu/common/anaconda3/lib/python3.7/site-packages/tornado/gen.py", line 1147, in run
    yielded = self.gen.send(value)
  File "/umbc/xfs1/jianwu/common/anaconda3/lib/python3.7/site-packages/distributed/deploy/local.py", line 217, in _start_worker
    raise gen.TimeoutError("Worker failed to start")
tornado.util.TimeoutError: Worker failed to start
tornado.application - ERROR - Multiple exceptions in yield list
Traceback (most recent call last):
  File "/umbc/xfs1/jianwu/common/anaconda3/lib/python3.7/site-packages/tornado/gen.py", line 883, in callback
    result_list.append(f.result())
  File "/umbc/xfs1/jianwu/common/anaconda3/lib/python3.7/site-packages/tornado/gen.py", line 1147, in run
    yielded = self.gen.send(value)
  File "/umbc/xfs1/jianwu/common/anaconda3/lib/python3.7/site-packages/distributed/deploy/local.py", line 217, in _start_worker
    raise gen.TimeoutError("Worker failed to start")
tornado.util.TimeoutError: Worker failed to start
tornado.application - ERROR - Multiple exceptions in yield list
Traceback (most recent call last):
  File "/umbc/xfs1/jianwu/common/anaconda3/lib/python3.7/site-packages/tornado/gen.py", line 883, in callback
    result_list.append(f.result())
  File "/umbc/xfs1/jianwu/common/anaconda3/lib/python3.7/site-packages/tornado/gen.py", line 1147, in run
    yielded = self.gen.send(value)
  File "/umbc/xfs1/jianwu/common/anaconda3/lib/python3.7/site-packages/distributed/deploy/local.py", line 217, in _start_worker
    raise gen.TimeoutError("Worker failed to start")
tornado.util.TimeoutError: Worker failed to start
tornado.application - ERROR - Multiple exceptions in yield list
Traceback (most recent call last):
  File "/umbc/xfs1/jianwu/common/anaconda3/lib/python3.7/site-packages/tornado/gen.py", line 883, in callback
    result_list.append(f.result())
  File "/umbc/xfs1/jianwu/common/anaconda3/lib/python3.7/site-packages/tornado/gen.py", line 1147, in run
    yielded = self.gen.send(value)
  File "/umbc/xfs1/jianwu/common/anaconda3/lib/python3.7/site-packages/distributed/deploy/local.py", line 217, in _start_worker
    raise gen.TimeoutError("Worker failed to start")
tornado.util.TimeoutError: Worker failed to start
tornado.application - ERROR - Multiple exceptions in yield list
Traceback (most recent call last):
  File "/umbc/xfs1/jianwu/common/anaconda3/lib/python3.7/site-packages/tornado/gen.py", line 883, in callback
    result_list.append(f.result())
  File "/umbc/xfs1/jianwu/common/anaconda3/lib/python3.7/site-packages/tornado/gen.py", line 1147, in run
    yielded = self.gen.send(value)
  File "/umbc/xfs1/jianwu/common/anaconda3/lib/python3.7/site-packages/distributed/deploy/local.py", line 217, in _start_worker
    raise gen.TimeoutError("Worker failed to start")
tornado.util.TimeoutError: Worker failed to start
tornado.application - ERROR - Multiple exceptions in yield list
Traceback (most recent call last):
  File "/umbc/xfs1/jianwu/common/anaconda3/lib/python3.7/site-packages/tornado/gen.py", line 883, in callback
    result_list.append(f.result())
  File "/umbc/xfs1/jianwu/common/anaconda3/lib/python3.7/site-packages/tornado/gen.py", line 1147, in run
    yielded = self.gen.send(value)
  File "/umbc/xfs1/jianwu/common/anaconda3/lib/python3.7/site-packages/distributed/deploy/local.py", line 217, in _start_worker
    raise gen.TimeoutError("Worker failed to start")
tornado.util.TimeoutError: Worker failed to start
tornado.application - ERROR - Multiple exceptions in yield list
Traceback (most recent call last):
  File "/umbc/xfs1/jianwu/common/anaconda3/lib/python3.7/site-packages/tornado/gen.py", line 883, in callback
    result_list.append(f.result())
  File "/umbc/xfs1/jianwu/common/anaconda3/lib/python3.7/site-packages/tornado/gen.py", line 1147, in run
    yielded = self.gen.send(value)
  File "/umbc/xfs1/jianwu/common/anaconda3/lib/python3.7/site-packages/distributed/deploy/local.py", line 217, in _start_worker
    raise gen.TimeoutError("Worker failed to start")
tornado.util.TimeoutError: Worker failed to start
tornado.application - ERROR - Multiple exceptions in yield list
Traceback (most recent call last):
  File "/umbc/xfs1/jianwu/common/anaconda3/lib/python3.7/site-packages/tornado/gen.py", line 883, in callback
    result_list.append(f.result())
  File "/umbc/xfs1/jianwu/common/anaconda3/lib/python3.7/site-packages/tornado/gen.py", line 1147, in run
    yielded = self.gen.send(value)
  File "/umbc/xfs1/jianwu/common/anaconda3/lib/python3.7/site-packages/distributed/deploy/local.py", line 217, in _start_worker
    raise gen.TimeoutError("Worker failed to start")
tornado.util.TimeoutError: Worker failed to start
tornado.application - ERROR - Multiple exceptions in yield list
Traceback (most recent call last):
  File "/umbc/xfs1/jianwu/common/anaconda3/lib/python3.7/site-packages/tornado/gen.py", line 883, in callback
    result_list.append(f.result())
  File "/umbc/xfs1/jianwu/common/anaconda3/lib/python3.7/site-packages/tornado/gen.py", line 1147, in run
    yielded = self.gen.send(value)
  File "/umbc/xfs1/jianwu/common/anaconda3/lib/python3.7/site-packages/distributed/deploy/local.py", line 217, in _start_worker
    raise gen.TimeoutError("Worker failed to start")
tornado.util.TimeoutError: Worker failed to start
tornado.application - ERROR - Multiple exceptions in yield list
Traceback (most recent call last):
  File "/umbc/xfs1/jianwu/common/anaconda3/lib/python3.7/site-packages/tornado/gen.py", line 883, in callback
    result_list.append(f.result())
  File "/umbc/xfs1/jianwu/common/anaconda3/lib/python3.7/site-packages/tornado/gen.py", line 1147, in run
    yielded = self.gen.send(value)
  File "/umbc/xfs1/jianwu/common/anaconda3/lib/python3.7/site-packages/distributed/deploy/local.py", line 217, in _start_worker
    raise gen.TimeoutError("Worker failed to start")
tornado.util.TimeoutError: Worker failed to start
tornado.application - ERROR - Multiple exceptions in yield list
Traceback (most recent call last):
  File "/umbc/xfs1/jianwu/common/anaconda3/lib/python3.7/site-packages/tornado/gen.py", line 883, in callback
    result_list.append(f.result())
  File "/umbc/xfs1/jianwu/common/anaconda3/lib/python3.7/site-packages/tornado/gen.py", line 1147, in run
    yielded = self.gen.send(value)
  File "/umbc/xfs1/jianwu/common/anaconda3/lib/python3.7/site-packages/distributed/deploy/local.py", line 217, in _start_worker
    raise gen.TimeoutError("Worker failed to start")
tornado.util.TimeoutError: Worker failed to start
Traceback (most recent call last):
  File "1m4ndk1.py", line 25, in <module>
    client = Client()
  File "/umbc/xfs1/jianwu/common/anaconda3/lib/python3.7/site-packages/distributed/client.py", line 636, in __init__
    self.start(timeout=timeout)
  File "/umbc/xfs1/jianwu/common/anaconda3/lib/python3.7/site-packages/distributed/client.py", line 759, in start
    sync(self.loop, self._start, **kwargs)
  File "/umbc/xfs1/jianwu/common/anaconda3/lib/python3.7/site-packages/distributed/utils.py", line 277, in sync
    six.reraise(*error[0])
  File "/umbc/xfs1/jianwu/common/anaconda3/lib/python3.7/site-packages/six.py", line 693, in reraise
    raise value
  File "/umbc/xfs1/jianwu/common/anaconda3/lib/python3.7/site-packages/distributed/utils.py", line 262, in f
    result[0] = yield future
  File "/umbc/xfs1/jianwu/common/anaconda3/lib/python3.7/site-packages/tornado/gen.py", line 1133, in run
    value = future.result()
  File "/umbc/xfs1/jianwu/common/anaconda3/lib/python3.7/site-packages/tornado/gen.py", line 1141, in run
    yielded = self.gen.throw(*exc_info)
  File "/umbc/xfs1/jianwu/common/anaconda3/lib/python3.7/site-packages/distributed/client.py", line 822, in _start
    yield self.cluster
  File "/umbc/xfs1/jianwu/common/anaconda3/lib/python3.7/site-packages/tornado/gen.py", line 1133, in run
    value = future.result()
  File "/umbc/xfs1/jianwu/common/anaconda3/lib/python3.7/asyncio/tasks.py", line 603, in _wrap_awaitable
    return (yield from awaitable.__await__())
  File "/umbc/xfs1/jianwu/common/anaconda3/lib/python3.7/site-packages/tornado/gen.py", line 1141, in run
    yielded = self.gen.throw(*exc_info)
  File "/umbc/xfs1/jianwu/common/anaconda3/lib/python3.7/site-packages/distributed/deploy/local.py", line 191, in _start
    yield [self._start_worker(**self.worker_kwargs) for i in range(n_workers)]
  File "/umbc/xfs1/jianwu/common/anaconda3/lib/python3.7/site-packages/tornado/gen.py", line 1133, in run
    value = future.result()
  File "/umbc/xfs1/jianwu/common/anaconda3/lib/python3.7/site-packages/tornado/gen.py", line 883, in callback
    result_list.append(f.result())
  File "/umbc/xfs1/jianwu/common/anaconda3/lib/python3.7/site-packages/tornado/gen.py", line 1147, in run
    yielded = self.gen.send(value)
  File "/umbc/xfs1/jianwu/common/anaconda3/lib/python3.7/site-packages/distributed/deploy/local.py", line 217, in _start_worker
    raise gen.TimeoutError("Worker failed to start")
tornado.util.TimeoutError: Worker failed to start
slurmstepd: error: proctrack_p_wait: Unable to destroy container 279575 in cgroup plugin, giving up after 128 sec
